*** Starting uWSGI 2.0.19.1 (64bit) on [Mon Jul 20 14:13:52 2020] ***
compiled with version: 8.3.0 on 20 July 2020 10:00:56
os: Linux-4.19.76-linuxkit #1 SMP Tue May 26 11:42:35 UTC 2020
nodename: 5d70340e2b94
machine: x86_64
clock source: unix
pcre jit disabled
detected number of CPU cores: 2
current working directory: /home/ares
writing pidfile to /home/ares/log/uwsgi.pid
detected binary path: /usr/local/bin/uwsgi
*** WARNING: you are running uWSGI as root !!! (use the --uid flag) *** 
chdir() to /home/ares
your memory page size is 4096 bytes
detected max file descriptor number: 1048576
lock engine: pthread robust mutexes
thunder lock: enabled
uwsgi socket 0 bound to TCP address 0.0.0.0:8000 fd 3
*** WARNING: you are running uWSGI as root !!! (use the --uid flag) *** 
Python version: 3.7.8 (default, Jun 30 2020, 18:27:23)  [GCC 8.3.0]
Python main interpreter initialized at 0x5605899c2410
*** WARNING: you are running uWSGI as root !!! (use the --uid flag) *** 
python threads support enabled
your server socket listen backlog is limited to 100 connections
your mercy for graceful operations on workers is 60 seconds
mapped 658704 bytes (643 KB) for 5 cores
*** Operational MODE: preforking ***
WSGI app 0 (mountpoint='') ready in 0 seconds on interpreter 0x5605899c2410 pid: 153 (default app)
*** WARNING: you are running uWSGI as root !!! (use the --uid flag) *** 
*** uWSGI is running in multiple interpreter mode ***
spawned uWSGI master process (pid: 153)
spawned uWSGI worker 1 (pid: 154, cores: 1)
spawned uWSGI worker 2 (pid: 155, cores: 1)
spawned uWSGI worker 3 (pid: 156, cores: 1)
spawned uWSGI worker 4 (pid: 157, cores: 1)
spawned uWSGI worker 5 (pid: 158, cores: 1)
Internal Server Error: /ajax/epgp
Traceback (most recent call last):
  File "/usr/local/lib/python3.7/site-packages/django/core/handlers/exception.py", line 34, in inner
    response = get_response(request)
  File "/usr/local/lib/python3.7/site-packages/django/utils/deprecation.py", line 93, in __call__
    response = self.process_request(request)
  File "/usr/local/lib/python3.7/site-packages/django/middleware/common.py", line 53, in process_request
    if self.should_redirect_with_slash(request):
  File "/usr/local/lib/python3.7/site-packages/django/middleware/common.py", line 71, in should_redirect_with_slash
    not is_valid_path(request.path_info, urlconf) and
  File "/usr/local/lib/python3.7/site-packages/django/urls/base.py", line 154, in is_valid_path
    resolve(path, urlconf)
  File "/usr/local/lib/python3.7/site-packages/django/urls/base.py", line 25, in resolve
    return get_resolver(urlconf).resolve(path)
  File "/usr/local/lib/python3.7/site-packages/django/urls/resolvers.py", line 546, in resolve
    sub_match = pattern.resolve(new_path)
  File "/usr/local/lib/python3.7/site-packages/django/urls/resolvers.py", line 546, in resolve
    sub_match = pattern.resolve(new_path)
AttributeError: 'str' object has no attribute 'resolve'
[pid: 154|app: 0|req: 1/1] 172.17.0.1 () {44 vars in 851 bytes} [Mon Jul 20 14:14:01 2020] GET /ajax/epgp => generated 75109 bytes in 88 msecs (HTTP/1.1 500) 2 headers in 96 bytes (1 switches on core 0)
Internal Server Error: /favicon.ico
Traceback (most recent call last):
  File "/usr/local/lib/python3.7/site-packages/django/core/handlers/exception.py", line 34, in inner
    response = get_response(request)
  File "/usr/local/lib/python3.7/site-packages/django/utils/deprecation.py", line 93, in __call__
    response = self.process_request(request)
  File "/usr/local/lib/python3.7/site-packages/django/middleware/common.py", line 53, in process_request
    if self.should_redirect_with_slash(request):
  File "/usr/local/lib/python3.7/site-packages/django/middleware/common.py", line 71, in should_redirect_with_slash
    not is_valid_path(request.path_info, urlconf) and
  File "/usr/local/lib/python3.7/site-packages/django/urls/base.py", line 154, in is_valid_path
    resolve(path, urlconf)
  File "/usr/local/lib/python3.7/site-packages/django/urls/base.py", line 25, in resolve
    return get_resolver(urlconf).resolve(path)
  File "/usr/local/lib/python3.7/site-packages/django/urls/resolvers.py", line 546, in resolve
    sub_match = pattern.resolve(new_path)
  File "/usr/local/lib/python3.7/site-packages/django/urls/resolvers.py", line 546, in resolve
    sub_match = pattern.resolve(new_path)
AttributeError: 'str' object has no attribute 'resolve'
[pid: 155|app: 0|req: 1/2] 172.17.0.1 () {42 vars in 749 bytes} [Mon Jul 20 14:14:01 2020] GET /favicon.ico => generated 74937 bytes in 77 msecs (HTTP/1.1 500) 2 headers in 96 bytes (1 switches on core 0)
Internal Server Error: /ajax/epgp
Traceback (most recent call last):
  File "/usr/local/lib/python3.7/site-packages/django/core/handlers/exception.py", line 34, in inner
    response = get_response(request)
  File "/usr/local/lib/python3.7/site-packages/django/utils/deprecation.py", line 93, in __call__
    response = self.process_request(request)
  File "/usr/local/lib/python3.7/site-packages/django/middleware/common.py", line 53, in process_request
    if self.should_redirect_with_slash(request):
  File "/usr/local/lib/python3.7/site-packages/django/middleware/common.py", line 71, in should_redirect_with_slash
    not is_valid_path(request.path_info, urlconf) and
  File "/usr/local/lib/python3.7/site-packages/django/urls/base.py", line 154, in is_valid_path
    resolve(path, urlconf)
  File "/usr/local/lib/python3.7/site-packages/django/urls/base.py", line 25, in resolve
    return get_resolver(urlconf).resolve(path)
  File "/usr/local/lib/python3.7/site-packages/django/urls/resolvers.py", line 546, in resolve
    sub_match = pattern.resolve(new_path)
  File "/usr/local/lib/python3.7/site-packages/django/urls/resolvers.py", line 546, in resolve
    sub_match = pattern.resolve(new_path)
AttributeError: 'str' object has no attribute 'resolve'
[pid: 156|app: 0|req: 1/3] 172.17.0.1 () {44 vars in 851 bytes} [Mon Jul 20 14:14:58 2020] GET /ajax/epgp => generated 75109 bytes in 75 msecs (HTTP/1.1 500) 2 headers in 96 bytes (1 switches on core 0)
Internal Server Error: /favicon.ico
Traceback (most recent call last):
  File "/usr/local/lib/python3.7/site-packages/django/core/handlers/exception.py", line 34, in inner
    response = get_response(request)
  File "/usr/local/lib/python3.7/site-packages/django/utils/deprecation.py", line 93, in __call__
    response = self.process_request(request)
  File "/usr/local/lib/python3.7/site-packages/django/middleware/common.py", line 53, in process_request
    if self.should_redirect_with_slash(request):
  File "/usr/local/lib/python3.7/site-packages/django/middleware/common.py", line 71, in should_redirect_with_slash
    not is_valid_path(request.path_info, urlconf) and
  File "/usr/local/lib/python3.7/site-packages/django/urls/base.py", line 154, in is_valid_path
    resolve(path, urlconf)
  File "/usr/local/lib/python3.7/site-packages/django/urls/base.py", line 25, in resolve
    return get_resolver(urlconf).resolve(path)
  File "/usr/local/lib/python3.7/site-packages/django/urls/resolvers.py", line 546, in resolve
    sub_match = pattern.resolve(new_path)
  File "/usr/local/lib/python3.7/site-packages/django/urls/resolvers.py", line 546, in resolve
    sub_match = pattern.resolve(new_path)
AttributeError: 'str' object has no attribute 'resolve'
[pid: 157|app: 0|req: 1/4] 172.17.0.1 () {42 vars in 749 bytes} [Mon Jul 20 14:14:58 2020] GET /favicon.ico => generated 74937 bytes in 67 msecs (HTTP/1.1 500) 2 headers in 96 bytes (1 switches on core 0)
Internal Server Error: /ajax/epgp
Traceback (most recent call last):
  File "/usr/local/lib/python3.7/site-packages/django/core/handlers/exception.py", line 34, in inner
    response = get_response(request)
  File "/usr/local/lib/python3.7/site-packages/django/utils/deprecation.py", line 93, in __call__
    response = self.process_request(request)
  File "/usr/local/lib/python3.7/site-packages/django/middleware/common.py", line 53, in process_request
    if self.should_redirect_with_slash(request):
  File "/usr/local/lib/python3.7/site-packages/django/middleware/common.py", line 71, in should_redirect_with_slash
    not is_valid_path(request.path_info, urlconf) and
  File "/usr/local/lib/python3.7/site-packages/django/urls/base.py", line 154, in is_valid_path
    resolve(path, urlconf)
  File "/usr/local/lib/python3.7/site-packages/django/urls/base.py", line 25, in resolve
    return get_resolver(urlconf).resolve(path)
  File "/usr/local/lib/python3.7/site-packages/django/urls/resolvers.py", line 546, in resolve
    sub_match = pattern.resolve(new_path)
  File "/usr/local/lib/python3.7/site-packages/django/urls/resolvers.py", line 546, in resolve
    sub_match = pattern.resolve(new_path)
AttributeError: 'str' object has no attribute 'resolve'
[pid: 158|app: 0|req: 1/5] 172.17.0.1 () {44 vars in 851 bytes} [Mon Jul 20 14:16:50 2020] GET /ajax/epgp => generated 75109 bytes in 83 msecs (HTTP/1.1 500) 2 headers in 96 bytes (1 switches on core 0)
Internal Server Error: /favicon.ico
Traceback (most recent call last):
  File "/usr/local/lib/python3.7/site-packages/django/core/handlers/exception.py", line 34, in inner
    response = get_response(request)
  File "/usr/local/lib/python3.7/site-packages/django/utils/deprecation.py", line 93, in __call__
    response = self.process_request(request)
  File "/usr/local/lib/python3.7/site-packages/django/middleware/common.py", line 53, in process_request
    if self.should_redirect_with_slash(request):
  File "/usr/local/lib/python3.7/site-packages/django/middleware/common.py", line 71, in should_redirect_with_slash
    not is_valid_path(request.path_info, urlconf) and
  File "/usr/local/lib/python3.7/site-packages/django/urls/base.py", line 154, in is_valid_path
    resolve(path, urlconf)
  File "/usr/local/lib/python3.7/site-packages/django/urls/base.py", line 25, in resolve
    return get_resolver(urlconf).resolve(path)
  File "/usr/local/lib/python3.7/site-packages/django/urls/resolvers.py", line 546, in resolve
    sub_match = pattern.resolve(new_path)
  File "/usr/local/lib/python3.7/site-packages/django/urls/resolvers.py", line 546, in resolve
    sub_match = pattern.resolve(new_path)
AttributeError: 'str' object has no attribute 'resolve'
[pid: 154|app: 0|req: 2/6] 172.17.0.1 () {42 vars in 749 bytes} [Mon Jul 20 14:16:50 2020] GET /favicon.ico => generated 74937 bytes in 41 msecs (HTTP/1.1 500) 2 headers in 96 bytes (1 switches on core 0)
[pid: 155|app: 0|req: 2/7] 172.17.0.1 () {44 vars in 833 bytes} [Mon Jul 20 14:23:08 2020] GET / => generated 6697 bytes in 19 msecs (HTTP/1.1 200) 4 headers in 137 bytes (1 switches on core 0)
Internal Server Error: /ajax/epgp
Traceback (most recent call last):
  File "/usr/local/lib/python3.7/site-packages/django/core/handlers/exception.py", line 34, in inner
    response = get_response(request)
  File "/usr/local/lib/python3.7/site-packages/django/utils/deprecation.py", line 93, in __call__
    response = self.process_request(request)
  File "/usr/local/lib/python3.7/site-packages/django/middleware/common.py", line 53, in process_request
    if self.should_redirect_with_slash(request):
  File "/usr/local/lib/python3.7/site-packages/django/middleware/common.py", line 71, in should_redirect_with_slash
    not is_valid_path(request.path_info, urlconf) and
  File "/usr/local/lib/python3.7/site-packages/django/urls/base.py", line 154, in is_valid_path
    resolve(path, urlconf)
  File "/usr/local/lib/python3.7/site-packages/django/urls/base.py", line 25, in resolve
    return get_resolver(urlconf).resolve(path)
  File "/usr/local/lib/python3.7/site-packages/django/urls/resolvers.py", line 546, in resolve
    sub_match = pattern.resolve(new_path)
  File "/usr/local/lib/python3.7/site-packages/django/urls/resolvers.py", line 546, in resolve
    sub_match = pattern.resolve(new_path)
AttributeError: 'str' object has no attribute 'resolve'
[pid: 156|app: 0|req: 2/8] 172.17.0.1 () {44 vars in 813 bytes} [Mon Jul 20 14:23:10 2020] GET /ajax/epgp?_=1595254989058 => generated 12366 bytes in 15 msecs (HTTP/1.1 500) 2 headers in 112 bytes (1 switches on core 0)
Internal Server Error: /ajax/epgp
Traceback (most recent call last):
  File "/usr/local/lib/python3.7/site-packages/django/core/handlers/exception.py", line 34, in inner
    response = get_response(request)
  File "/usr/local/lib/python3.7/site-packages/django/utils/deprecation.py", line 93, in __call__
    response = self.process_request(request)
  File "/usr/local/lib/python3.7/site-packages/django/middleware/common.py", line 53, in process_request
    if self.should_redirect_with_slash(request):
  File "/usr/local/lib/python3.7/site-packages/django/middleware/common.py", line 71, in should_redirect_with_slash
    not is_valid_path(request.path_info, urlconf) and
  File "/usr/local/lib/python3.7/site-packages/django/urls/base.py", line 154, in is_valid_path
    resolve(path, urlconf)
  File "/usr/local/lib/python3.7/site-packages/django/urls/base.py", line 25, in resolve
    return get_resolver(urlconf).resolve(path)
  File "/usr/local/lib/python3.7/site-packages/django/urls/resolvers.py", line 546, in resolve
    sub_match = pattern.resolve(new_path)
  File "/usr/local/lib/python3.7/site-packages/django/urls/resolvers.py", line 546, in resolve
    sub_match = pattern.resolve(new_path)
AttributeError: 'str' object has no attribute 'resolve'
[pid: 157|app: 0|req: 2/9] 172.17.0.1 () {42 vars in 851 bytes} [Mon Jul 20 14:23:13 2020] GET /ajax/epgp?_=1595254989058 => generated 75394 bytes in 42 msecs (HTTP/1.1 500) 2 headers in 96 bytes (1 switches on core 0)
Internal Server Error: /ajax/epgp
Traceback (most recent call last):
  File "/usr/local/lib/python3.7/site-packages/django/core/handlers/exception.py", line 34, in inner
    response = get_response(request)
  File "/usr/local/lib/python3.7/site-packages/django/utils/deprecation.py", line 93, in __call__
    response = self.process_request(request)
  File "/usr/local/lib/python3.7/site-packages/django/middleware/common.py", line 53, in process_request
    if self.should_redirect_with_slash(request):
  File "/usr/local/lib/python3.7/site-packages/django/middleware/common.py", line 71, in should_redirect_with_slash
    not is_valid_path(request.path_info, urlconf) and
  File "/usr/local/lib/python3.7/site-packages/django/urls/base.py", line 154, in is_valid_path
    resolve(path, urlconf)
  File "/usr/local/lib/python3.7/site-packages/django/urls/base.py", line 25, in resolve
    return get_resolver(urlconf).resolve(path)
  File "/usr/local/lib/python3.7/site-packages/django/urls/resolvers.py", line 546, in resolve
    sub_match = pattern.resolve(new_path)
  File "/usr/local/lib/python3.7/site-packages/django/urls/resolvers.py", line 546, in resolve
    sub_match = pattern.resolve(new_path)
AttributeError: 'str' object has no attribute 'resolve'
[pid: 158|app: 0|req: 2/10] 172.17.0.1 () {44 vars in 882 bytes} [Mon Jul 20 14:23:20 2020] GET /ajax/epgp?_=1595254989058 => generated 75531 bytes in 37 msecs (HTTP/1.1 500) 2 headers in 96 bytes (1 switches on core 0)
Internal Server Error: /ajax/epgp
Traceback (most recent call last):
  File "/usr/local/lib/python3.7/site-packages/django/core/handlers/exception.py", line 34, in inner
    response = get_response(request)
  File "/usr/local/lib/python3.7/site-packages/django/utils/deprecation.py", line 93, in __call__
    response = self.process_request(request)
  File "/usr/local/lib/python3.7/site-packages/django/middleware/common.py", line 53, in process_request
    if self.should_redirect_with_slash(request):
  File "/usr/local/lib/python3.7/site-packages/django/middleware/common.py", line 71, in should_redirect_with_slash
    not is_valid_path(request.path_info, urlconf) and
  File "/usr/local/lib/python3.7/site-packages/django/urls/base.py", line 154, in is_valid_path
    resolve(path, urlconf)
  File "/usr/local/lib/python3.7/site-packages/django/urls/base.py", line 25, in resolve
    return get_resolver(urlconf).resolve(path)
  File "/usr/local/lib/python3.7/site-packages/django/urls/resolvers.py", line 546, in resolve
    sub_match = pattern.resolve(new_path)
  File "/usr/local/lib/python3.7/site-packages/django/urls/resolvers.py", line 546, in resolve
    sub_match = pattern.resolve(new_path)
AttributeError: 'str' object has no attribute 'resolve'
[pid: 154|app: 0|req: 3/11] 172.17.0.1 () {44 vars in 882 bytes} [Mon Jul 20 14:23:21 2020] GET /ajax/epgp?_=1595254989058 => generated 75531 bytes in 39 msecs (HTTP/1.1 500) 2 headers in 96 bytes (1 switches on core 0)
[pid: 155|app: 0|req: 3/12] 172.17.0.1 () {44 vars in 853 bytes} [Mon Jul 20 14:23:26 2020] GET /ajax/epgp/ => generated 3 bytes in 0 msecs (HTTP/1.1 200) 4 headers in 134 bytes (1 switches on core 0)
[pid: 156|app: 0|req: 3/13] 172.17.0.1 () {44 vars in 853 bytes} [Mon Jul 20 14:23:27 2020] GET /ajax/epgp/ => generated 110 bytes in 10 msecs (HTTP/1.1 200) 4 headers in 136 bytes (1 switches on core 0)
[pid: 157|app: 0|req: 3/14] 172.17.0.1 () {42 vars in 822 bytes} [Mon Jul 20 14:23:30 2020] GET /ajax/epgp/ => generated 110 bytes in 7 msecs (HTTP/1.1 200) 4 headers in 136 bytes (1 switches on core 0)
[pid: 158|app: 0|req: 3/15] 172.17.0.1 () {44 vars in 853 bytes} [Mon Jul 20 14:23:31 2020] GET /ajax/epgp/ => generated 110 bytes in 10 msecs (HTTP/1.1 200) 4 headers in 136 bytes (1 switches on core 0)
Internal Server Error: /ajax/epgp
Traceback (most recent call last):
  File "/usr/local/lib/python3.7/site-packages/django/core/handlers/exception.py", line 34, in inner
    response = get_response(request)
  File "/usr/local/lib/python3.7/site-packages/django/utils/deprecation.py", line 93, in __call__
    response = self.process_request(request)
  File "/usr/local/lib/python3.7/site-packages/django/middleware/common.py", line 53, in process_request
    if self.should_redirect_with_slash(request):
  File "/usr/local/lib/python3.7/site-packages/django/middleware/common.py", line 71, in should_redirect_with_slash
    not is_valid_path(request.path_info, urlconf) and
  File "/usr/local/lib/python3.7/site-packages/django/urls/base.py", line 154, in is_valid_path
    resolve(path, urlconf)
  File "/usr/local/lib/python3.7/site-packages/django/urls/base.py", line 25, in resolve
    return get_resolver(urlconf).resolve(path)
  File "/usr/local/lib/python3.7/site-packages/django/urls/resolvers.py", line 546, in resolve
    sub_match = pattern.resolve(new_path)
  File "/usr/local/lib/python3.7/site-packages/django/urls/resolvers.py", line 546, in resolve
    sub_match = pattern.resolve(new_path)
AttributeError: 'str' object has no attribute 'resolve'
[pid: 154|app: 0|req: 4/16] 172.17.0.1 () {42 vars in 851 bytes} [Mon Jul 20 14:23:34 2020] GET /ajax/epgp?_=1595254989058 => generated 75394 bytes in 46 msecs (HTTP/1.1 500) 2 headers in 96 bytes (1 switches on core 0)
Internal Server Error: /ajax/epgp
Traceback (most recent call last):
  File "/usr/local/lib/python3.7/site-packages/django/core/handlers/exception.py", line 34, in inner
    response = get_response(request)
  File "/usr/local/lib/python3.7/site-packages/django/utils/deprecation.py", line 93, in __call__
    response = self.process_request(request)
  File "/usr/local/lib/python3.7/site-packages/django/middleware/common.py", line 53, in process_request
    if self.should_redirect_with_slash(request):
  File "/usr/local/lib/python3.7/site-packages/django/middleware/common.py", line 71, in should_redirect_with_slash
    not is_valid_path(request.path_info, urlconf) and
  File "/usr/local/lib/python3.7/site-packages/django/urls/base.py", line 154, in is_valid_path
    resolve(path, urlconf)
  File "/usr/local/lib/python3.7/site-packages/django/urls/base.py", line 25, in resolve
    return get_resolver(urlconf).resolve(path)
  File "/usr/local/lib/python3.7/site-packages/django/urls/resolvers.py", line 546, in resolve
    sub_match = pattern.resolve(new_path)
  File "/usr/local/lib/python3.7/site-packages/django/urls/resolvers.py", line 546, in resolve
    sub_match = pattern.resolve(new_path)
AttributeError: 'str' object has no attribute 'resolve'
[pid: 155|app: 0|req: 4/17] 172.17.0.1 () {44 vars in 882 bytes} [Mon Jul 20 14:23:36 2020] GET /ajax/epgp?_=1595254989058 => generated 75531 bytes in 36 msecs (HTTP/1.1 500) 2 headers in 96 bytes (1 switches on core 0)
Internal Server Error: /ajax/epgp
Traceback (most recent call last):
  File "/usr/local/lib/python3.7/site-packages/django/core/handlers/exception.py", line 34, in inner
    response = get_response(request)
  File "/usr/local/lib/python3.7/site-packages/django/utils/deprecation.py", line 93, in __call__
    response = self.process_request(request)
  File "/usr/local/lib/python3.7/site-packages/django/middleware/common.py", line 53, in process_request
    if self.should_redirect_with_slash(request):
  File "/usr/local/lib/python3.7/site-packages/django/middleware/common.py", line 71, in should_redirect_with_slash
    not is_valid_path(request.path_info, urlconf) and
  File "/usr/local/lib/python3.7/site-packages/django/urls/base.py", line 154, in is_valid_path
    resolve(path, urlconf)
  File "/usr/local/lib/python3.7/site-packages/django/urls/base.py", line 25, in resolve
    return get_resolver(urlconf).resolve(path)
  File "/usr/local/lib/python3.7/site-packages/django/urls/resolvers.py", line 546, in resolve
    sub_match = pattern.resolve(new_path)
  File "/usr/local/lib/python3.7/site-packages/django/urls/resolvers.py", line 546, in resolve
    sub_match = pattern.resolve(new_path)
AttributeError: 'str' object has no attribute 'resolve'
[pid: 156|app: 0|req: 4/18] 172.17.0.1 () {44 vars in 882 bytes} [Mon Jul 20 14:23:37 2020] GET /ajax/epgp?_=1595254989058 => generated 75531 bytes in 34 msecs (HTTP/1.1 500) 2 headers in 96 bytes (1 switches on core 0)
uwsgi_proto_uwsgi_parser(): Success [proto/uwsgi.c line 40]
[pid: 158|app: 0|req: 4/19] 172.17.0.1 () {50 vars in 961 bytes} [Mon Jul 20 14:23:47 2020] GET / => generated 6697 bytes in 16 msecs (HTTP/1.1 200) 4 headers in 137 bytes (1 switches on core 0)
Internal Server Error: /favicon.ico
Traceback (most recent call last):
  File "/usr/local/lib/python3.7/site-packages/django/core/handlers/exception.py", line 34, in inner
    response = get_response(request)
  File "/usr/local/lib/python3.7/site-packages/django/utils/deprecation.py", line 93, in __call__
    response = self.process_request(request)
  File "/usr/local/lib/python3.7/site-packages/django/middleware/common.py", line 53, in process_request
    if self.should_redirect_with_slash(request):
  File "/usr/local/lib/python3.7/site-packages/django/middleware/common.py", line 71, in should_redirect_with_slash
    not is_valid_path(request.path_info, urlconf) and
  File "/usr/local/lib/python3.7/site-packages/django/urls/base.py", line 154, in is_valid_path
    resolve(path, urlconf)
  File "/usr/local/lib/python3.7/site-packages/django/urls/base.py", line 25, in resolve
    return get_resolver(urlconf).resolve(path)
  File "/usr/local/lib/python3.7/site-packages/django/urls/resolvers.py", line 546, in resolve
    sub_match = pattern.resolve(new_path)
  File "/usr/local/lib/python3.7/site-packages/django/urls/resolvers.py", line 546, in resolve
    sub_match = pattern.resolve(new_path)
AttributeError: 'str' object has no attribute 'resolve'
[pid: 154|app: 0|req: 5/20] 172.17.0.1 () {48 vars in 874 bytes} [Mon Jul 20 14:23:47 2020] GET /favicon.ico => generated 75548 bytes in 37 msecs (HTTP/1.1 500) 2 headers in 96 bytes (1 switches on core 0)
Internal Server Error: /ajax/epgp
Traceback (most recent call last):
  File "/usr/local/lib/python3.7/site-packages/django/core/handlers/exception.py", line 34, in inner
    response = get_response(request)
  File "/usr/local/lib/python3.7/site-packages/django/utils/deprecation.py", line 93, in __call__
    response = self.process_request(request)
  File "/usr/local/lib/python3.7/site-packages/django/middleware/common.py", line 53, in process_request
    if self.should_redirect_with_slash(request):
  File "/usr/local/lib/python3.7/site-packages/django/middleware/common.py", line 71, in should_redirect_with_slash
    not is_valid_path(request.path_info, urlconf) and
  File "/usr/local/lib/python3.7/site-packages/django/urls/base.py", line 154, in is_valid_path
    resolve(path, urlconf)
  File "/usr/local/lib/python3.7/site-packages/django/urls/base.py", line 25, in resolve
    return get_resolver(urlconf).resolve(path)
  File "/usr/local/lib/python3.7/site-packages/django/urls/resolvers.py", line 546, in resolve
    sub_match = pattern.resolve(new_path)
  File "/usr/local/lib/python3.7/site-packages/django/urls/resolvers.py", line 546, in resolve
    sub_match = pattern.resolve(new_path)
AttributeError: 'str' object has no attribute 'resolve'
[pid: 155|app: 0|req: 5/21] 172.17.0.1 () {50 vars in 944 bytes} [Mon Jul 20 14:23:49 2020] GET /ajax/epgp?_=1595255027825 => generated 12547 bytes in 20 msecs (HTTP/1.1 500) 2 headers in 112 bytes (1 switches on core 0)
[pid: 156|app: 0|req: 5/22] 172.17.0.1 () {52 vars in 992 bytes} [Mon Jul 20 14:23:54 2020] GET / => generated 6697 bytes in 16 msecs (HTTP/1.1 200) 4 headers in 137 bytes (1 switches on core 0)
Internal Server Error: /favicon.ico
Traceback (most recent call last):
  File "/usr/local/lib/python3.7/site-packages/django/core/handlers/exception.py", line 34, in inner
    response = get_response(request)
  File "/usr/local/lib/python3.7/site-packages/django/utils/deprecation.py", line 93, in __call__
    response = self.process_request(request)
  File "/usr/local/lib/python3.7/site-packages/django/middleware/common.py", line 53, in process_request
    if self.should_redirect_with_slash(request):
  File "/usr/local/lib/python3.7/site-packages/django/middleware/common.py", line 71, in should_redirect_with_slash
    not is_valid_path(request.path_info, urlconf) and
  File "/usr/local/lib/python3.7/site-packages/django/urls/base.py", line 154, in is_valid_path
    resolve(path, urlconf)
  File "/usr/local/lib/python3.7/site-packages/django/urls/base.py", line 25, in resolve
    return get_resolver(urlconf).resolve(path)
  File "/usr/local/lib/python3.7/site-packages/django/urls/resolvers.py", line 546, in resolve
    sub_match = pattern.resolve(new_path)
  File "/usr/local/lib/python3.7/site-packages/django/urls/resolvers.py", line 546, in resolve
    sub_match = pattern.resolve(new_path)
AttributeError: 'str' object has no attribute 'resolve'
[pid: 157|app: 0|req: 4/23] 172.17.0.1 () {52 vars in 927 bytes} [Mon Jul 20 14:23:54 2020] GET /favicon.ico => generated 75813 bytes in 47 msecs (HTTP/1.1 500) 2 headers in 96 bytes (1 switches on core 0)
Internal Server Error: /ajax/epgp
Traceback (most recent call last):
  File "/usr/local/lib/python3.7/site-packages/django/core/handlers/exception.py", line 34, in inner
    response = get_response(request)
  File "/usr/local/lib/python3.7/site-packages/django/utils/deprecation.py", line 93, in __call__
    response = self.process_request(request)
  File "/usr/local/lib/python3.7/site-packages/django/middleware/common.py", line 53, in process_request
    if self.should_redirect_with_slash(request):
  File "/usr/local/lib/python3.7/site-packages/django/middleware/common.py", line 71, in should_redirect_with_slash
    not is_valid_path(request.path_info, urlconf) and
  File "/usr/local/lib/python3.7/site-packages/django/urls/base.py", line 154, in is_valid_path
    resolve(path, urlconf)
  File "/usr/local/lib/python3.7/site-packages/django/urls/base.py", line 25, in resolve
    return get_resolver(urlconf).resolve(path)
  File "/usr/local/lib/python3.7/site-packages/django/urls/resolvers.py", line 546, in resolve
    sub_match = pattern.resolve(new_path)
  File "/usr/local/lib/python3.7/site-packages/django/urls/resolvers.py", line 546, in resolve
    sub_match = pattern.resolve(new_path)
AttributeError: 'str' object has no attribute 'resolve'
[pid: 158|app: 0|req: 5/24] 172.17.0.1 () {50 vars in 944 bytes} [Mon Jul 20 14:23:55 2020] GET /ajax/epgp?_=1595255034256 => generated 12547 bytes in 16 msecs (HTTP/1.1 500) 2 headers in 112 bytes (1 switches on core 0)
Internal Server Error: /ajax/epgp
Traceback (most recent call last):
  File "/usr/local/lib/python3.7/site-packages/django/core/handlers/exception.py", line 34, in inner
    response = get_response(request)
  File "/usr/local/lib/python3.7/site-packages/django/utils/deprecation.py", line 93, in __call__
    response = self.process_request(request)
  File "/usr/local/lib/python3.7/site-packages/django/middleware/common.py", line 53, in process_request
    if self.should_redirect_with_slash(request):
  File "/usr/local/lib/python3.7/site-packages/django/middleware/common.py", line 71, in should_redirect_with_slash
    not is_valid_path(request.path_info, urlconf) and
  File "/usr/local/lib/python3.7/site-packages/django/urls/base.py", line 154, in is_valid_path
    resolve(path, urlconf)
  File "/usr/local/lib/python3.7/site-packages/django/urls/base.py", line 25, in resolve
    return get_resolver(urlconf).resolve(path)
  File "/usr/local/lib/python3.7/site-packages/django/urls/resolvers.py", line 546, in resolve
    sub_match = pattern.resolve(new_path)
  File "/usr/local/lib/python3.7/site-packages/django/urls/resolvers.py", line 546, in resolve
    sub_match = pattern.resolve(new_path)
AttributeError: 'str' object has no attribute 'resolve'
[pid: 154|app: 0|req: 6/25] 172.17.0.1 () {48 vars in 985 bytes} [Mon Jul 20 14:23:57 2020] GET /ajax/epgp?_=1595255034256 => generated 76014 bytes in 43 msecs (HTTP/1.1 500) 2 headers in 96 bytes (1 switches on core 0)
Internal Server Error: /favicon.ico
Traceback (most recent call last):
  File "/usr/local/lib/python3.7/site-packages/django/core/handlers/exception.py", line 34, in inner
    response = get_response(request)
  File "/usr/local/lib/python3.7/site-packages/django/utils/deprecation.py", line 93, in __call__
    response = self.process_request(request)
  File "/usr/local/lib/python3.7/site-packages/django/middleware/common.py", line 53, in process_request
    if self.should_redirect_with_slash(request):
  File "/usr/local/lib/python3.7/site-packages/django/middleware/common.py", line 71, in should_redirect_with_slash
    not is_valid_path(request.path_info, urlconf) and
  File "/usr/local/lib/python3.7/site-packages/django/urls/base.py", line 154, in is_valid_path
    resolve(path, urlconf)
  File "/usr/local/lib/python3.7/site-packages/django/urls/base.py", line 25, in resolve
    return get_resolver(urlconf).resolve(path)
  File "/usr/local/lib/python3.7/site-packages/django/urls/resolvers.py", line 546, in resolve
    sub_match = pattern.resolve(new_path)
  File "/usr/local/lib/python3.7/site-packages/django/urls/resolvers.py", line 546, in resolve
    sub_match = pattern.resolve(new_path)
AttributeError: 'str' object has no attribute 'resolve'
[pid: 155|app: 0|req: 6/26] 172.17.0.1 () {48 vars in 899 bytes} [Mon Jul 20 14:23:57 2020] GET /favicon.ico => generated 75573 bytes in 36 msecs (HTTP/1.1 500) 2 headers in 96 bytes (1 switches on core 0)
Internal Server Error: /ajax/epgp
Traceback (most recent call last):
  File "/usr/local/lib/python3.7/site-packages/django/core/handlers/exception.py", line 34, in inner
    response = get_response(request)
  File "/usr/local/lib/python3.7/site-packages/django/utils/deprecation.py", line 93, in __call__
    response = self.process_request(request)
  File "/usr/local/lib/python3.7/site-packages/django/middleware/common.py", line 53, in process_request
    if self.should_redirect_with_slash(request):
  File "/usr/local/lib/python3.7/site-packages/django/middleware/common.py", line 71, in should_redirect_with_slash
    not is_valid_path(request.path_info, urlconf) and
  File "/usr/local/lib/python3.7/site-packages/django/urls/base.py", line 154, in is_valid_path
    resolve(path, urlconf)
  File "/usr/local/lib/python3.7/site-packages/django/urls/base.py", line 25, in resolve
    return get_resolver(urlconf).resolve(path)
  File "/usr/local/lib/python3.7/site-packages/django/urls/resolvers.py", line 546, in resolve
    sub_match = pattern.resolve(new_path)
  File "/usr/local/lib/python3.7/site-packages/django/urls/resolvers.py", line 546, in resolve
    sub_match = pattern.resolve(new_path)
AttributeError: 'str' object has no attribute 'resolve'
[pid: 156|app: 0|req: 6/27] 172.17.0.1 () {52 vars in 1041 bytes} [Mon Jul 20 14:24:03 2020] GET /ajax/epgp?_=1595255034256 => generated 76282 bytes in 37 msecs (HTTP/1.1 500) 2 headers in 96 bytes (1 switches on core 0)
Internal Server Error: /favicon.ico
Traceback (most recent call last):
  File "/usr/local/lib/python3.7/site-packages/django/core/handlers/exception.py", line 34, in inner
    response = get_response(request)
  File "/usr/local/lib/python3.7/site-packages/django/utils/deprecation.py", line 93, in __call__
    response = self.process_request(request)
  File "/usr/local/lib/python3.7/site-packages/django/middleware/common.py", line 53, in process_request
    if self.should_redirect_with_slash(request):
  File "/usr/local/lib/python3.7/site-packages/django/middleware/common.py", line 71, in should_redirect_with_slash
    not is_valid_path(request.path_info, urlconf) and
  File "/usr/local/lib/python3.7/site-packages/django/urls/base.py", line 154, in is_valid_path
    resolve(path, urlconf)
  File "/usr/local/lib/python3.7/site-packages/django/urls/base.py", line 25, in resolve
    return get_resolver(urlconf).resolve(path)
  File "/usr/local/lib/python3.7/site-packages/django/urls/resolvers.py", line 546, in resolve
    sub_match = pattern.resolve(new_path)
  File "/usr/local/lib/python3.7/site-packages/django/urls/resolvers.py", line 546, in resolve
    sub_match = pattern.resolve(new_path)
AttributeError: 'str' object has no attribute 'resolve'
[pid: 157|app: 0|req: 5/28] 172.17.0.1 () {48 vars in 899 bytes} [Mon Jul 20 14:24:03 2020] GET /favicon.ico => generated 75573 bytes in 38 msecs (HTTP/1.1 500) 2 headers in 96 bytes (1 switches on core 0)
Internal Server Error: /ajax/epgp
Traceback (most recent call last):
  File "/usr/local/lib/python3.7/site-packages/django/core/handlers/exception.py", line 34, in inner
    response = get_response(request)
  File "/usr/local/lib/python3.7/site-packages/django/utils/deprecation.py", line 93, in __call__
    response = self.process_request(request)
  File "/usr/local/lib/python3.7/site-packages/django/middleware/common.py", line 53, in process_request
    if self.should_redirect_with_slash(request):
  File "/usr/local/lib/python3.7/site-packages/django/middleware/common.py", line 71, in should_redirect_with_slash
    not is_valid_path(request.path_info, urlconf) and
  File "/usr/local/lib/python3.7/site-packages/django/urls/base.py", line 154, in is_valid_path
    resolve(path, urlconf)
  File "/usr/local/lib/python3.7/site-packages/django/urls/base.py", line 25, in resolve
    return get_resolver(urlconf).resolve(path)
  File "/usr/local/lib/python3.7/site-packages/django/urls/resolvers.py", line 546, in resolve
    sub_match = pattern.resolve(new_path)
  File "/usr/local/lib/python3.7/site-packages/django/urls/resolvers.py", line 546, in resolve
    sub_match = pattern.resolve(new_path)
AttributeError: 'str' object has no attribute 'resolve'
[pid: 158|app: 0|req: 6/29] 172.17.0.1 () {52 vars in 1041 bytes} [Mon Jul 20 14:24:04 2020] GET /ajax/epgp?_=1595255034256 => generated 76282 bytes in 35 msecs (HTTP/1.1 500) 2 headers in 96 bytes (1 switches on core 0)
Internal Server Error: /favicon.ico
Traceback (most recent call last):
  File "/usr/local/lib/python3.7/site-packages/django/core/handlers/exception.py", line 34, in inner
    response = get_response(request)
  File "/usr/local/lib/python3.7/site-packages/django/utils/deprecation.py", line 93, in __call__
    response = self.process_request(request)
  File "/usr/local/lib/python3.7/site-packages/django/middleware/common.py", line 53, in process_request
    if self.should_redirect_with_slash(request):
  File "/usr/local/lib/python3.7/site-packages/django/middleware/common.py", line 71, in should_redirect_with_slash
    not is_valid_path(request.path_info, urlconf) and
  File "/usr/local/lib/python3.7/site-packages/django/urls/base.py", line 154, in is_valid_path
    resolve(path, urlconf)
  File "/usr/local/lib/python3.7/site-packages/django/urls/base.py", line 25, in resolve
    return get_resolver(urlconf).resolve(path)
  File "/usr/local/lib/python3.7/site-packages/django/urls/resolvers.py", line 546, in resolve
    sub_match = pattern.resolve(new_path)
  File "/usr/local/lib/python3.7/site-packages/django/urls/resolvers.py", line 546, in resolve
    sub_match = pattern.resolve(new_path)
AttributeError: 'str' object has no attribute 'resolve'
[pid: 154|app: 0|req: 7/30] 172.17.0.1 () {48 vars in 899 bytes} [Mon Jul 20 14:24:04 2020] GET /favicon.ico => generated 75573 bytes in 37 msecs (HTTP/1.1 500) 2 headers in 96 bytes (1 switches on core 0)
Internal Server Error: /ajax/epgp
Traceback (most recent call last):
  File "/usr/local/lib/python3.7/site-packages/django/core/handlers/exception.py", line 34, in inner
    response = get_response(request)
  File "/usr/local/lib/python3.7/site-packages/django/utils/deprecation.py", line 93, in __call__
    response = self.process_request(request)
  File "/usr/local/lib/python3.7/site-packages/django/middleware/common.py", line 53, in process_request
    if self.should_redirect_with_slash(request):
  File "/usr/local/lib/python3.7/site-packages/django/middleware/common.py", line 71, in should_redirect_with_slash
    not is_valid_path(request.path_info, urlconf) and
  File "/usr/local/lib/python3.7/site-packages/django/urls/base.py", line 154, in is_valid_path
    resolve(path, urlconf)
  File "/usr/local/lib/python3.7/site-packages/django/urls/base.py", line 25, in resolve
    return get_resolver(urlconf).resolve(path)
  File "/usr/local/lib/python3.7/site-packages/django/urls/resolvers.py", line 546, in resolve
    sub_match = pattern.resolve(new_path)
  File "/usr/local/lib/python3.7/site-packages/django/urls/resolvers.py", line 546, in resolve
    sub_match = pattern.resolve(new_path)
AttributeError: 'str' object has no attribute 'resolve'
[pid: 155|app: 0|req: 7/31] 172.17.0.1 () {52 vars in 1041 bytes} [Mon Jul 20 14:24:05 2020] GET /ajax/epgp?_=1595255034256 => generated 76282 bytes in 35 msecs (HTTP/1.1 500) 2 headers in 96 bytes (1 switches on core 0)
Internal Server Error: /favicon.ico
Traceback (most recent call last):
  File "/usr/local/lib/python3.7/site-packages/django/core/handlers/exception.py", line 34, in inner
    response = get_response(request)
  File "/usr/local/lib/python3.7/site-packages/django/utils/deprecation.py", line 93, in __call__
    response = self.process_request(request)
  File "/usr/local/lib/python3.7/site-packages/django/middleware/common.py", line 53, in process_request
    if self.should_redirect_with_slash(request):
  File "/usr/local/lib/python3.7/site-packages/django/middleware/common.py", line 71, in should_redirect_with_slash
    not is_valid_path(request.path_info, urlconf) and
  File "/usr/local/lib/python3.7/site-packages/django/urls/base.py", line 154, in is_valid_path
    resolve(path, urlconf)
  File "/usr/local/lib/python3.7/site-packages/django/urls/base.py", line 25, in resolve
    return get_resolver(urlconf).resolve(path)
  File "/usr/local/lib/python3.7/site-packages/django/urls/resolvers.py", line 546, in resolve
    sub_match = pattern.resolve(new_path)
  File "/usr/local/lib/python3.7/site-packages/django/urls/resolvers.py", line 546, in resolve
    sub_match = pattern.resolve(new_path)
AttributeError: 'str' object has no attribute 'resolve'
[pid: 156|app: 0|req: 7/32] 172.17.0.1 () {48 vars in 899 bytes} [Mon Jul 20 14:24:05 2020] GET /favicon.ico => generated 75573 bytes in 44 msecs (HTTP/1.1 500) 2 headers in 96 bytes (1 switches on core 0)
Internal Server Error: /ajax/epgp
Traceback (most recent call last):
  File "/usr/local/lib/python3.7/site-packages/django/core/handlers/exception.py", line 34, in inner
    response = get_response(request)
  File "/usr/local/lib/python3.7/site-packages/django/utils/deprecation.py", line 93, in __call__
    response = self.process_request(request)
  File "/usr/local/lib/python3.7/site-packages/django/middleware/common.py", line 53, in process_request
    if self.should_redirect_with_slash(request):
  File "/usr/local/lib/python3.7/site-packages/django/middleware/common.py", line 71, in should_redirect_with_slash
    not is_valid_path(request.path_info, urlconf) and
  File "/usr/local/lib/python3.7/site-packages/django/urls/base.py", line 154, in is_valid_path
    resolve(path, urlconf)
  File "/usr/local/lib/python3.7/site-packages/django/urls/base.py", line 25, in resolve
    return get_resolver(urlconf).resolve(path)
  File "/usr/local/lib/python3.7/site-packages/django/urls/resolvers.py", line 546, in resolve
    sub_match = pattern.resolve(new_path)
  File "/usr/local/lib/python3.7/site-packages/django/urls/resolvers.py", line 546, in resolve
    sub_match = pattern.resolve(new_path)
AttributeError: 'str' object has no attribute 'resolve'
[pid: 157|app: 0|req: 6/33] 172.17.0.1 () {52 vars in 1041 bytes} [Mon Jul 20 14:24:25 2020] GET /ajax/epgp?_=1595255034256 => generated 76282 bytes in 37 msecs (HTTP/1.1 500) 2 headers in 96 bytes (1 switches on core 0)
Internal Server Error: /favicon.ico
Traceback (most recent call last):
  File "/usr/local/lib/python3.7/site-packages/django/core/handlers/exception.py", line 34, in inner
    response = get_response(request)
  File "/usr/local/lib/python3.7/site-packages/django/utils/deprecation.py", line 93, in __call__
    response = self.process_request(request)
  File "/usr/local/lib/python3.7/site-packages/django/middleware/common.py", line 53, in process_request
    if self.should_redirect_with_slash(request):
  File "/usr/local/lib/python3.7/site-packages/django/middleware/common.py", line 71, in should_redirect_with_slash
    not is_valid_path(request.path_info, urlconf) and
  File "/usr/local/lib/python3.7/site-packages/django/urls/base.py", line 154, in is_valid_path
    resolve(path, urlconf)
  File "/usr/local/lib/python3.7/site-packages/django/urls/base.py", line 25, in resolve
    return get_resolver(urlconf).resolve(path)
  File "/usr/local/lib/python3.7/site-packages/django/urls/resolvers.py", line 546, in resolve
    sub_match = pattern.resolve(new_path)
  File "/usr/local/lib/python3.7/site-packages/django/urls/resolvers.py", line 546, in resolve
    sub_match = pattern.resolve(new_path)
AttributeError: 'str' object has no attribute 'resolve'
[pid: 158|app: 0|req: 7/34] 172.17.0.1 () {48 vars in 899 bytes} [Mon Jul 20 14:24:26 2020] GET /favicon.ico => generated 75573 bytes in 46 msecs (HTTP/1.1 500) 2 headers in 96 bytes (1 switches on core 0)
Internal Server Error: /ajax/epgp
Traceback (most recent call last):
  File "/usr/local/lib/python3.7/site-packages/django/core/handlers/exception.py", line 34, in inner
    response = get_response(request)
  File "/usr/local/lib/python3.7/site-packages/django/utils/deprecation.py", line 93, in __call__
    response = self.process_request(request)
  File "/usr/local/lib/python3.7/site-packages/django/middleware/common.py", line 53, in process_request
    if self.should_redirect_with_slash(request):
  File "/usr/local/lib/python3.7/site-packages/django/middleware/common.py", line 71, in should_redirect_with_slash
    not is_valid_path(request.path_info, urlconf) and
  File "/usr/local/lib/python3.7/site-packages/django/urls/base.py", line 154, in is_valid_path
    resolve(path, urlconf)
  File "/usr/local/lib/python3.7/site-packages/django/urls/base.py", line 25, in resolve
    return get_resolver(urlconf).resolve(path)
  File "/usr/local/lib/python3.7/site-packages/django/urls/resolvers.py", line 546, in resolve
    sub_match = pattern.resolve(new_path)
  File "/usr/local/lib/python3.7/site-packages/django/urls/resolvers.py", line 546, in resolve
    sub_match = pattern.resolve(new_path)
AttributeError: 'str' object has no attribute 'resolve'
[pid: 154|app: 0|req: 8/35] 172.17.0.1 () {52 vars in 1041 bytes} [Mon Jul 20 14:24:26 2020] GET /ajax/epgp?_=1595255034256 => generated 76282 bytes in 36 msecs (HTTP/1.1 500) 2 headers in 96 bytes (1 switches on core 0)
Internal Server Error: /favicon.ico
Traceback (most recent call last):
  File "/usr/local/lib/python3.7/site-packages/django/core/handlers/exception.py", line 34, in inner
    response = get_response(request)
  File "/usr/local/lib/python3.7/site-packages/django/utils/deprecation.py", line 93, in __call__
    response = self.process_request(request)
  File "/usr/local/lib/python3.7/site-packages/django/middleware/common.py", line 53, in process_request
    if self.should_redirect_with_slash(request):
  File "/usr/local/lib/python3.7/site-packages/django/middleware/common.py", line 71, in should_redirect_with_slash
    not is_valid_path(request.path_info, urlconf) and
  File "/usr/local/lib/python3.7/site-packages/django/urls/base.py", line 154, in is_valid_path
    resolve(path, urlconf)
  File "/usr/local/lib/python3.7/site-packages/django/urls/base.py", line 25, in resolve
    return get_resolver(urlconf).resolve(path)
  File "/usr/local/lib/python3.7/site-packages/django/urls/resolvers.py", line 546, in resolve
    sub_match = pattern.resolve(new_path)
  File "/usr/local/lib/python3.7/site-packages/django/urls/resolvers.py", line 546, in resolve
    sub_match = pattern.resolve(new_path)
AttributeError: 'str' object has no attribute 'resolve'
[pid: 155|app: 0|req: 8/36] 172.17.0.1 () {48 vars in 899 bytes} [Mon Jul 20 14:24:26 2020] GET /favicon.ico => generated 75573 bytes in 36 msecs (HTTP/1.1 500) 2 headers in 96 bytes (1 switches on core 0)
Internal Server Error: /ajax/epgp
Traceback (most recent call last):
  File "/usr/local/lib/python3.7/site-packages/django/core/handlers/exception.py", line 34, in inner
    response = get_response(request)
  File "/usr/local/lib/python3.7/site-packages/django/utils/deprecation.py", line 93, in __call__
    response = self.process_request(request)
  File "/usr/local/lib/python3.7/site-packages/django/middleware/common.py", line 53, in process_request
    if self.should_redirect_with_slash(request):
  File "/usr/local/lib/python3.7/site-packages/django/middleware/common.py", line 71, in should_redirect_with_slash
    not is_valid_path(request.path_info, urlconf) and
  File "/usr/local/lib/python3.7/site-packages/django/urls/base.py", line 154, in is_valid_path
    resolve(path, urlconf)
  File "/usr/local/lib/python3.7/site-packages/django/urls/base.py", line 25, in resolve
    return get_resolver(urlconf).resolve(path)
  File "/usr/local/lib/python3.7/site-packages/django/urls/resolvers.py", line 546, in resolve
    sub_match = pattern.resolve(new_path)
  File "/usr/local/lib/python3.7/site-packages/django/urls/resolvers.py", line 546, in resolve
    sub_match = pattern.resolve(new_path)
AttributeError: 'str' object has no attribute 'resolve'
[pid: 156|app: 0|req: 8/37] 172.17.0.1 () {50 vars in 979 bytes} [Mon Jul 20 14:24:28 2020] GET /ajax/epgp => generated 75723 bytes in 36 msecs (HTTP/1.1 500) 2 headers in 96 bytes (1 switches on core 0)
Internal Server Error: /favicon.ico
Traceback (most recent call last):
  File "/usr/local/lib/python3.7/site-packages/django/core/handlers/exception.py", line 34, in inner
    response = get_response(request)
  File "/usr/local/lib/python3.7/site-packages/django/utils/deprecation.py", line 93, in __call__
    response = self.process_request(request)
  File "/usr/local/lib/python3.7/site-packages/django/middleware/common.py", line 53, in process_request
    if self.should_redirect_with_slash(request):
  File "/usr/local/lib/python3.7/site-packages/django/middleware/common.py", line 71, in should_redirect_with_slash
    not is_valid_path(request.path_info, urlconf) and
  File "/usr/local/lib/python3.7/site-packages/django/urls/base.py", line 154, in is_valid_path
    resolve(path, urlconf)
  File "/usr/local/lib/python3.7/site-packages/django/urls/base.py", line 25, in resolve
    return get_resolver(urlconf).resolve(path)
  File "/usr/local/lib/python3.7/site-packages/django/urls/resolvers.py", line 546, in resolve
    sub_match = pattern.resolve(new_path)
  File "/usr/local/lib/python3.7/site-packages/django/urls/resolvers.py", line 546, in resolve
    sub_match = pattern.resolve(new_path)
AttributeError: 'str' object has no attribute 'resolve'
[pid: 157|app: 0|req: 7/38] 172.17.0.1 () {48 vars in 883 bytes} [Mon Jul 20 14:24:28 2020] GET /favicon.ico => generated 75557 bytes in 38 msecs (HTTP/1.1 500) 2 headers in 96 bytes (1 switches on core 0)
Internal Server Error: /ajax/epgp
Traceback (most recent call last):
  File "/usr/local/lib/python3.7/site-packages/django/core/handlers/exception.py", line 34, in inner
    response = get_response(request)
  File "/usr/local/lib/python3.7/site-packages/django/utils/deprecation.py", line 93, in __call__
    response = self.process_request(request)
  File "/usr/local/lib/python3.7/site-packages/django/middleware/common.py", line 53, in process_request
    if self.should_redirect_with_slash(request):
  File "/usr/local/lib/python3.7/site-packages/django/middleware/common.py", line 71, in should_redirect_with_slash
    not is_valid_path(request.path_info, urlconf) and
  File "/usr/local/lib/python3.7/site-packages/django/urls/base.py", line 154, in is_valid_path
    resolve(path, urlconf)
  File "/usr/local/lib/python3.7/site-packages/django/urls/base.py", line 25, in resolve
    return get_resolver(urlconf).resolve(path)
  File "/usr/local/lib/python3.7/site-packages/django/urls/resolvers.py", line 546, in resolve
    sub_match = pattern.resolve(new_path)
  File "/usr/local/lib/python3.7/site-packages/django/urls/resolvers.py", line 546, in resolve
    sub_match = pattern.resolve(new_path)
AttributeError: 'str' object has no attribute 'resolve'
[pid: 158|app: 0|req: 8/39] 172.17.0.1 () {52 vars in 1010 bytes} [Mon Jul 20 14:24:29 2020] GET /ajax/epgp => generated 75860 bytes in 35 msecs (HTTP/1.1 500) 2 headers in 96 bytes (1 switches on core 0)
Internal Server Error: /favicon.ico
Traceback (most recent call last):
  File "/usr/local/lib/python3.7/site-packages/django/core/handlers/exception.py", line 34, in inner
    response = get_response(request)
  File "/usr/local/lib/python3.7/site-packages/django/utils/deprecation.py", line 93, in __call__
    response = self.process_request(request)
  File "/usr/local/lib/python3.7/site-packages/django/middleware/common.py", line 53, in process_request
    if self.should_redirect_with_slash(request):
  File "/usr/local/lib/python3.7/site-packages/django/middleware/common.py", line 71, in should_redirect_with_slash
    not is_valid_path(request.path_info, urlconf) and
  File "/usr/local/lib/python3.7/site-packages/django/urls/base.py", line 154, in is_valid_path
    resolve(path, urlconf)
  File "/usr/local/lib/python3.7/site-packages/django/urls/base.py", line 25, in resolve
    return get_resolver(urlconf).resolve(path)
  File "/usr/local/lib/python3.7/site-packages/django/urls/resolvers.py", line 546, in resolve
    sub_match = pattern.resolve(new_path)
  File "/usr/local/lib/python3.7/site-packages/django/urls/resolvers.py", line 546, in resolve
    sub_match = pattern.resolve(new_path)
AttributeError: 'str' object has no attribute 'resolve'
[pid: 154|app: 0|req: 9/40] 172.17.0.1 () {48 vars in 883 bytes} [Mon Jul 20 14:24:29 2020] GET /favicon.ico => generated 75557 bytes in 36 msecs (HTTP/1.1 500) 2 headers in 96 bytes (1 switches on core 0)
Internal Server Error: /ajax/epgp
Traceback (most recent call last):
  File "/usr/local/lib/python3.7/site-packages/django/core/handlers/exception.py", line 34, in inner
    response = get_response(request)
  File "/usr/local/lib/python3.7/site-packages/django/utils/deprecation.py", line 93, in __call__
    response = self.process_request(request)
  File "/usr/local/lib/python3.7/site-packages/django/middleware/common.py", line 53, in process_request
    if self.should_redirect_with_slash(request):
  File "/usr/local/lib/python3.7/site-packages/django/middleware/common.py", line 71, in should_redirect_with_slash
    not is_valid_path(request.path_info, urlconf) and
  File "/usr/local/lib/python3.7/site-packages/django/urls/base.py", line 154, in is_valid_path
    resolve(path, urlconf)
  File "/usr/local/lib/python3.7/site-packages/django/urls/base.py", line 25, in resolve
    return get_resolver(urlconf).resolve(path)
  File "/usr/local/lib/python3.7/site-packages/django/urls/resolvers.py", line 546, in resolve
    sub_match = pattern.resolve(new_path)
  File "/usr/local/lib/python3.7/site-packages/django/urls/resolvers.py", line 546, in resolve
    sub_match = pattern.resolve(new_path)
AttributeError: 'str' object has no attribute 'resolve'
[pid: 155|app: 0|req: 9/41] 172.17.0.1 () {52 vars in 1010 bytes} [Mon Jul 20 14:24:30 2020] GET /ajax/epgp => generated 75860 bytes in 37 msecs (HTTP/1.1 500) 2 headers in 96 bytes (1 switches on core 0)
Internal Server Error: /favicon.ico
Traceback (most recent call last):
  File "/usr/local/lib/python3.7/site-packages/django/core/handlers/exception.py", line 34, in inner
    response = get_response(request)
  File "/usr/local/lib/python3.7/site-packages/django/utils/deprecation.py", line 93, in __call__
    response = self.process_request(request)
  File "/usr/local/lib/python3.7/site-packages/django/middleware/common.py", line 53, in process_request
    if self.should_redirect_with_slash(request):
  File "/usr/local/lib/python3.7/site-packages/django/middleware/common.py", line 71, in should_redirect_with_slash
    not is_valid_path(request.path_info, urlconf) and
  File "/usr/local/lib/python3.7/site-packages/django/urls/base.py", line 154, in is_valid_path
    resolve(path, urlconf)
  File "/usr/local/lib/python3.7/site-packages/django/urls/base.py", line 25, in resolve
    return get_resolver(urlconf).resolve(path)
  File "/usr/local/lib/python3.7/site-packages/django/urls/resolvers.py", line 546, in resolve
    sub_match = pattern.resolve(new_path)
  File "/usr/local/lib/python3.7/site-packages/django/urls/resolvers.py", line 546, in resolve
    sub_match = pattern.resolve(new_path)
AttributeError: 'str' object has no attribute 'resolve'
[pid: 156|app: 0|req: 9/42] 172.17.0.1 () {48 vars in 883 bytes} [Mon Jul 20 14:24:30 2020] GET /favicon.ico => generated 75557 bytes in 36 msecs (HTTP/1.1 500) 2 headers in 96 bytes (1 switches on core 0)
Internal Server Error: /ajax/epgp
Traceback (most recent call last):
  File "/usr/local/lib/python3.7/site-packages/django/core/handlers/exception.py", line 34, in inner
    response = get_response(request)
  File "/usr/local/lib/python3.7/site-packages/django/utils/deprecation.py", line 93, in __call__
    response = self.process_request(request)
  File "/usr/local/lib/python3.7/site-packages/django/middleware/common.py", line 53, in process_request
    if self.should_redirect_with_slash(request):
  File "/usr/local/lib/python3.7/site-packages/django/middleware/common.py", line 71, in should_redirect_with_slash
    not is_valid_path(request.path_info, urlconf) and
  File "/usr/local/lib/python3.7/site-packages/django/urls/base.py", line 154, in is_valid_path
    resolve(path, urlconf)
  File "/usr/local/lib/python3.7/site-packages/django/urls/base.py", line 25, in resolve
    return get_resolver(urlconf).resolve(path)
  File "/usr/local/lib/python3.7/site-packages/django/urls/resolvers.py", line 546, in resolve
    sub_match = pattern.resolve(new_path)
  File "/usr/local/lib/python3.7/site-packages/django/urls/resolvers.py", line 546, in resolve
    sub_match = pattern.resolve(new_path)
AttributeError: 'str' object has no attribute 'resolve'
[pid: 157|app: 0|req: 8/43] 172.17.0.1 () {52 vars in 1010 bytes} [Mon Jul 20 14:24:39 2020] GET /ajax/epgp => generated 75860 bytes in 42 msecs (HTTP/1.1 500) 2 headers in 96 bytes (1 switches on core 0)
Internal Server Error: /favicon.ico
Traceback (most recent call last):
  File "/usr/local/lib/python3.7/site-packages/django/core/handlers/exception.py", line 34, in inner
    response = get_response(request)
  File "/usr/local/lib/python3.7/site-packages/django/utils/deprecation.py", line 93, in __call__
    response = self.process_request(request)
  File "/usr/local/lib/python3.7/site-packages/django/middleware/common.py", line 53, in process_request
    if self.should_redirect_with_slash(request):
  File "/usr/local/lib/python3.7/site-packages/django/middleware/common.py", line 71, in should_redirect_with_slash
    not is_valid_path(request.path_info, urlconf) and
  File "/usr/local/lib/python3.7/site-packages/django/urls/base.py", line 154, in is_valid_path
    resolve(path, urlconf)
  File "/usr/local/lib/python3.7/site-packages/django/urls/base.py", line 25, in resolve
    return get_resolver(urlconf).resolve(path)
  File "/usr/local/lib/python3.7/site-packages/django/urls/resolvers.py", line 546, in resolve
    sub_match = pattern.resolve(new_path)
  File "/usr/local/lib/python3.7/site-packages/django/urls/resolvers.py", line 546, in resolve
    sub_match = pattern.resolve(new_path)
AttributeError: 'str' object has no attribute 'resolve'
[pid: 158|app: 0|req: 9/44] 172.17.0.1 () {48 vars in 883 bytes} [Mon Jul 20 14:24:39 2020] GET /favicon.ico => generated 75557 bytes in 41 msecs (HTTP/1.1 500) 2 headers in 96 bytes (1 switches on core 0)
Internal Server Error: /ajax/epgp
Traceback (most recent call last):
  File "/usr/local/lib/python3.7/site-packages/django/core/handlers/exception.py", line 34, in inner
    response = get_response(request)
  File "/usr/local/lib/python3.7/site-packages/django/utils/deprecation.py", line 93, in __call__
    response = self.process_request(request)
  File "/usr/local/lib/python3.7/site-packages/django/middleware/common.py", line 53, in process_request
    if self.should_redirect_with_slash(request):
  File "/usr/local/lib/python3.7/site-packages/django/middleware/common.py", line 71, in should_redirect_with_slash
    not is_valid_path(request.path_info, urlconf) and
  File "/usr/local/lib/python3.7/site-packages/django/urls/base.py", line 154, in is_valid_path
    resolve(path, urlconf)
  File "/usr/local/lib/python3.7/site-packages/django/urls/base.py", line 25, in resolve
    return get_resolver(urlconf).resolve(path)
  File "/usr/local/lib/python3.7/site-packages/django/urls/resolvers.py", line 546, in resolve
    sub_match = pattern.resolve(new_path)
  File "/usr/local/lib/python3.7/site-packages/django/urls/resolvers.py", line 546, in resolve
    sub_match = pattern.resolve(new_path)
AttributeError: 'str' object has no attribute 'resolve'
[pid: 154|app: 0|req: 10/45] 172.17.0.1 () {52 vars in 1010 bytes} [Mon Jul 20 14:24:40 2020] GET /ajax/epgp => generated 75860 bytes in 43 msecs (HTTP/1.1 500) 2 headers in 96 bytes (1 switches on core 0)
Internal Server Error: /favicon.ico
Traceback (most recent call last):
  File "/usr/local/lib/python3.7/site-packages/django/core/handlers/exception.py", line 34, in inner
    response = get_response(request)
  File "/usr/local/lib/python3.7/site-packages/django/utils/deprecation.py", line 93, in __call__
    response = self.process_request(request)
  File "/usr/local/lib/python3.7/site-packages/django/middleware/common.py", line 53, in process_request
    if self.should_redirect_with_slash(request):
  File "/usr/local/lib/python3.7/site-packages/django/middleware/common.py", line 71, in should_redirect_with_slash
    not is_valid_path(request.path_info, urlconf) and
  File "/usr/local/lib/python3.7/site-packages/django/urls/base.py", line 154, in is_valid_path
    resolve(path, urlconf)
  File "/usr/local/lib/python3.7/site-packages/django/urls/base.py", line 25, in resolve
    return get_resolver(urlconf).resolve(path)
  File "/usr/local/lib/python3.7/site-packages/django/urls/resolvers.py", line 546, in resolve
    sub_match = pattern.resolve(new_path)
  File "/usr/local/lib/python3.7/site-packages/django/urls/resolvers.py", line 546, in resolve
    sub_match = pattern.resolve(new_path)
AttributeError: 'str' object has no attribute 'resolve'
[pid: 155|app: 0|req: 10/46] 172.17.0.1 () {48 vars in 883 bytes} [Mon Jul 20 14:24:40 2020] GET /favicon.ico => generated 75557 bytes in 40 msecs (HTTP/1.1 500) 2 headers in 96 bytes (1 switches on core 0)
Internal Server Error: /ajax/epgp
Traceback (most recent call last):
  File "/usr/local/lib/python3.7/site-packages/django/core/handlers/exception.py", line 34, in inner
    response = get_response(request)
  File "/usr/local/lib/python3.7/site-packages/django/utils/deprecation.py", line 93, in __call__
    response = self.process_request(request)
  File "/usr/local/lib/python3.7/site-packages/django/middleware/common.py", line 53, in process_request
    if self.should_redirect_with_slash(request):
  File "/usr/local/lib/python3.7/site-packages/django/middleware/common.py", line 71, in should_redirect_with_slash
    not is_valid_path(request.path_info, urlconf) and
  File "/usr/local/lib/python3.7/site-packages/django/urls/base.py", line 154, in is_valid_path
    resolve(path, urlconf)
  File "/usr/local/lib/python3.7/site-packages/django/urls/base.py", line 25, in resolve
    return get_resolver(urlconf).resolve(path)
  File "/usr/local/lib/python3.7/site-packages/django/urls/resolvers.py", line 546, in resolve
    sub_match = pattern.resolve(new_path)
  File "/usr/local/lib/python3.7/site-packages/django/urls/resolvers.py", line 546, in resolve
    sub_match = pattern.resolve(new_path)
AttributeError: 'str' object has no attribute 'resolve'
[pid: 156|app: 0|req: 10/47] 172.17.0.1 () {52 vars in 1010 bytes} [Mon Jul 20 14:24:41 2020] GET /ajax/epgp => generated 75860 bytes in 37 msecs (HTTP/1.1 500) 2 headers in 96 bytes (1 switches on core 0)
Internal Server Error: /favicon.ico
Traceback (most recent call last):
  File "/usr/local/lib/python3.7/site-packages/django/core/handlers/exception.py", line 34, in inner
    response = get_response(request)
  File "/usr/local/lib/python3.7/site-packages/django/utils/deprecation.py", line 93, in __call__
    response = self.process_request(request)
  File "/usr/local/lib/python3.7/site-packages/django/middleware/common.py", line 53, in process_request
    if self.should_redirect_with_slash(request):
  File "/usr/local/lib/python3.7/site-packages/django/middleware/common.py", line 71, in should_redirect_with_slash
    not is_valid_path(request.path_info, urlconf) and
  File "/usr/local/lib/python3.7/site-packages/django/urls/base.py", line 154, in is_valid_path
    resolve(path, urlconf)
  File "/usr/local/lib/python3.7/site-packages/django/urls/base.py", line 25, in resolve
    return get_resolver(urlconf).resolve(path)
  File "/usr/local/lib/python3.7/site-packages/django/urls/resolvers.py", line 546, in resolve
    sub_match = pattern.resolve(new_path)
  File "/usr/local/lib/python3.7/site-packages/django/urls/resolvers.py", line 546, in resolve
    sub_match = pattern.resolve(new_path)
AttributeError: 'str' object has no attribute 'resolve'
[pid: 157|app: 0|req: 9/48] 172.17.0.1 () {48 vars in 883 bytes} [Mon Jul 20 14:24:41 2020] GET /favicon.ico => generated 75557 bytes in 40 msecs (HTTP/1.1 500) 2 headers in 96 bytes (1 switches on core 0)
Internal Server Error: /ajax/epgp
Traceback (most recent call last):
  File "/usr/local/lib/python3.7/site-packages/django/core/handlers/exception.py", line 34, in inner
    response = get_response(request)
  File "/usr/local/lib/python3.7/site-packages/django/utils/deprecation.py", line 93, in __call__
    response = self.process_request(request)
  File "/usr/local/lib/python3.7/site-packages/django/middleware/common.py", line 53, in process_request
    if self.should_redirect_with_slash(request):
  File "/usr/local/lib/python3.7/site-packages/django/middleware/common.py", line 71, in should_redirect_with_slash
    not is_valid_path(request.path_info, urlconf) and
  File "/usr/local/lib/python3.7/site-packages/django/urls/base.py", line 154, in is_valid_path
    resolve(path, urlconf)
  File "/usr/local/lib/python3.7/site-packages/django/urls/base.py", line 25, in resolve
    return get_resolver(urlconf).resolve(path)
  File "/usr/local/lib/python3.7/site-packages/django/urls/resolvers.py", line 546, in resolve
    sub_match = pattern.resolve(new_path)
  File "/usr/local/lib/python3.7/site-packages/django/urls/resolvers.py", line 546, in resolve
    sub_match = pattern.resolve(new_path)
AttributeError: 'str' object has no attribute 'resolve'
[pid: 158|app: 0|req: 10/49] 172.17.0.1 () {52 vars in 1010 bytes} [Mon Jul 20 14:24:41 2020] GET /ajax/epgp => generated 75860 bytes in 35 msecs (HTTP/1.1 500) 2 headers in 96 bytes (1 switches on core 0)
Internal Server Error: /favicon.ico
Traceback (most recent call last):
  File "/usr/local/lib/python3.7/site-packages/django/core/handlers/exception.py", line 34, in inner
    response = get_response(request)
  File "/usr/local/lib/python3.7/site-packages/django/utils/deprecation.py", line 93, in __call__
    response = self.process_request(request)
  File "/usr/local/lib/python3.7/site-packages/django/middleware/common.py", line 53, in process_request
    if self.should_redirect_with_slash(request):
  File "/usr/local/lib/python3.7/site-packages/django/middleware/common.py", line 71, in should_redirect_with_slash
    not is_valid_path(request.path_info, urlconf) and
  File "/usr/local/lib/python3.7/site-packages/django/urls/base.py", line 154, in is_valid_path
    resolve(path, urlconf)
  File "/usr/local/lib/python3.7/site-packages/django/urls/base.py", line 25, in resolve
    return get_resolver(urlconf).resolve(path)
  File "/usr/local/lib/python3.7/site-packages/django/urls/resolvers.py", line 546, in resolve
    sub_match = pattern.resolve(new_path)
  File "/usr/local/lib/python3.7/site-packages/django/urls/resolvers.py", line 546, in resolve
    sub_match = pattern.resolve(new_path)
AttributeError: 'str' object has no attribute 'resolve'
[pid: 154|app: 0|req: 11/50] 172.17.0.1 () {48 vars in 883 bytes} [Mon Jul 20 14:24:42 2020] GET /favicon.ico => generated 75557 bytes in 34 msecs (HTTP/1.1 500) 2 headers in 96 bytes (1 switches on core 0)
Internal Server Error: /ajax/epgp
Traceback (most recent call last):
  File "/usr/local/lib/python3.7/site-packages/django/core/handlers/exception.py", line 34, in inner
    response = get_response(request)
  File "/usr/local/lib/python3.7/site-packages/django/utils/deprecation.py", line 93, in __call__
    response = self.process_request(request)
  File "/usr/local/lib/python3.7/site-packages/django/middleware/common.py", line 53, in process_request
    if self.should_redirect_with_slash(request):
  File "/usr/local/lib/python3.7/site-packages/django/middleware/common.py", line 71, in should_redirect_with_slash
    not is_valid_path(request.path_info, urlconf) and
  File "/usr/local/lib/python3.7/site-packages/django/urls/base.py", line 154, in is_valid_path
    resolve(path, urlconf)
  File "/usr/local/lib/python3.7/site-packages/django/urls/base.py", line 25, in resolve
    return get_resolver(urlconf).resolve(path)
  File "/usr/local/lib/python3.7/site-packages/django/urls/resolvers.py", line 546, in resolve
    sub_match = pattern.resolve(new_path)
  File "/usr/local/lib/python3.7/site-packages/django/urls/resolvers.py", line 546, in resolve
    sub_match = pattern.resolve(new_path)
AttributeError: 'str' object has no attribute 'resolve'
[pid: 156|app: 0|req: 11/51] 172.17.0.1 () {52 vars in 1010 bytes} [Mon Jul 20 14:24:46 2020] GET /ajax/epgp => generated 75860 bytes in 37 msecs (HTTP/1.1 500) 2 headers in 96 bytes (1 switches on core 0)
Internal Server Error: /favicon.ico
Traceback (most recent call last):
  File "/usr/local/lib/python3.7/site-packages/django/core/handlers/exception.py", line 34, in inner
    response = get_response(request)
  File "/usr/local/lib/python3.7/site-packages/django/utils/deprecation.py", line 93, in __call__
    response = self.process_request(request)
  File "/usr/local/lib/python3.7/site-packages/django/middleware/common.py", line 53, in process_request
    if self.should_redirect_with_slash(request):
  File "/usr/local/lib/python3.7/site-packages/django/middleware/common.py", line 71, in should_redirect_with_slash
    not is_valid_path(request.path_info, urlconf) and
  File "/usr/local/lib/python3.7/site-packages/django/urls/base.py", line 154, in is_valid_path
    resolve(path, urlconf)
  File "/usr/local/lib/python3.7/site-packages/django/urls/base.py", line 25, in resolve
    return get_resolver(urlconf).resolve(path)
  File "/usr/local/lib/python3.7/site-packages/django/urls/resolvers.py", line 546, in resolve
    sub_match = pattern.resolve(new_path)
  File "/usr/local/lib/python3.7/site-packages/django/urls/resolvers.py", line 546, in resolve
    sub_match = pattern.resolve(new_path)
AttributeError: 'str' object has no attribute 'resolve'
[pid: 157|app: 0|req: 10/52] 172.17.0.1 () {48 vars in 883 bytes} [Mon Jul 20 14:24:46 2020] GET /favicon.ico => generated 75557 bytes in 35 msecs (HTTP/1.1 500) 2 headers in 96 bytes (1 switches on core 0)
[pid: 158|app: 0|req: 11/53] 172.17.0.1 () {50 vars in 961 bytes} [Mon Jul 20 14:24:55 2020] GET / => generated 6697 bytes in 6 msecs (HTTP/1.1 200) 4 headers in 137 bytes (1 switches on core 0)
Internal Server Error: /favicon.ico
Traceback (most recent call last):
  File "/usr/local/lib/python3.7/site-packages/django/core/handlers/exception.py", line 34, in inner
    response = get_response(request)
  File "/usr/local/lib/python3.7/site-packages/django/utils/deprecation.py", line 93, in __call__
    response = self.process_request(request)
  File "/usr/local/lib/python3.7/site-packages/django/middleware/common.py", line 53, in process_request
    if self.should_redirect_with_slash(request):
  File "/usr/local/lib/python3.7/site-packages/django/middleware/common.py", line 71, in should_redirect_with_slash
    not is_valid_path(request.path_info, urlconf) and
  File "/usr/local/lib/python3.7/site-packages/django/urls/base.py", line 154, in is_valid_path
    resolve(path, urlconf)
  File "/usr/local/lib/python3.7/site-packages/django/urls/base.py", line 25, in resolve
    return get_resolver(urlconf).resolve(path)
  File "/usr/local/lib/python3.7/site-packages/django/urls/resolvers.py", line 546, in resolve
    sub_match = pattern.resolve(new_path)
  File "/usr/local/lib/python3.7/site-packages/django/urls/resolvers.py", line 546, in resolve
    sub_match = pattern.resolve(new_path)
AttributeError: 'str' object has no attribute 'resolve'
[pid: 154|app: 0|req: 12/54] 172.17.0.1 () {48 vars in 874 bytes} [Mon Jul 20 14:24:55 2020] GET /favicon.ico => generated 75548 bytes in 35 msecs (HTTP/1.1 500) 2 headers in 96 bytes (1 switches on core 0)
[pid: 155|app: 0|req: 11/55] 172.17.0.1 () {52 vars in 992 bytes} [Mon Jul 20 14:25:02 2020] GET / => generated 6697 bytes in 6 msecs (HTTP/1.1 200) 4 headers in 137 bytes (1 switches on core 0)
Internal Server Error: /favicon.ico
Traceback (most recent call last):
  File "/usr/local/lib/python3.7/site-packages/django/core/handlers/exception.py", line 34, in inner
    response = get_response(request)
  File "/usr/local/lib/python3.7/site-packages/django/utils/deprecation.py", line 93, in __call__
    response = self.process_request(request)
  File "/usr/local/lib/python3.7/site-packages/django/middleware/common.py", line 53, in process_request
    if self.should_redirect_with_slash(request):
  File "/usr/local/lib/python3.7/site-packages/django/middleware/common.py", line 71, in should_redirect_with_slash
    not is_valid_path(request.path_info, urlconf) and
  File "/usr/local/lib/python3.7/site-packages/django/urls/base.py", line 154, in is_valid_path
    resolve(path, urlconf)
  File "/usr/local/lib/python3.7/site-packages/django/urls/base.py", line 25, in resolve
    return get_resolver(urlconf).resolve(path)
  File "/usr/local/lib/python3.7/site-packages/django/urls/resolvers.py", line 546, in resolve
    sub_match = pattern.resolve(new_path)
  File "/usr/local/lib/python3.7/site-packages/django/urls/resolvers.py", line 546, in resolve
    sub_match = pattern.resolve(new_path)
AttributeError: 'str' object has no attribute 'resolve'
[pid: 156|app: 0|req: 12/56] 172.17.0.1 () {48 vars in 874 bytes} [Mon Jul 20 14:25:02 2020] GET /favicon.ico => generated 75548 bytes in 35 msecs (HTTP/1.1 500) 2 headers in 96 bytes (1 switches on core 0)
[pid: 157|app: 0|req: 11/57] 172.17.0.1 () {52 vars in 992 bytes} [Mon Jul 20 14:25:03 2020] GET / => generated 6697 bytes in 13 msecs (HTTP/1.1 200) 4 headers in 137 bytes (1 switches on core 0)
Internal Server Error: /favicon.ico
Traceback (most recent call last):
  File "/usr/local/lib/python3.7/site-packages/django/core/handlers/exception.py", line 34, in inner
    response = get_response(request)
  File "/usr/local/lib/python3.7/site-packages/django/utils/deprecation.py", line 93, in __call__
    response = self.process_request(request)
  File "/usr/local/lib/python3.7/site-packages/django/middleware/common.py", line 53, in process_request
    if self.should_redirect_with_slash(request):
  File "/usr/local/lib/python3.7/site-packages/django/middleware/common.py", line 71, in should_redirect_with_slash
    not is_valid_path(request.path_info, urlconf) and
  File "/usr/local/lib/python3.7/site-packages/django/urls/base.py", line 154, in is_valid_path
    resolve(path, urlconf)
  File "/usr/local/lib/python3.7/site-packages/django/urls/base.py", line 25, in resolve
    return get_resolver(urlconf).resolve(path)
  File "/usr/local/lib/python3.7/site-packages/django/urls/resolvers.py", line 546, in resolve
    sub_match = pattern.resolve(new_path)
  File "/usr/local/lib/python3.7/site-packages/django/urls/resolvers.py", line 546, in resolve
    sub_match = pattern.resolve(new_path)
AttributeError: 'str' object has no attribute 'resolve'
[pid: 158|app: 0|req: 12/58] 172.17.0.1 () {48 vars in 874 bytes} [Mon Jul 20 14:25:03 2020] GET /favicon.ico => generated 75548 bytes in 42 msecs (HTTP/1.1 500) 2 headers in 96 bytes (1 switches on core 0)
[pid: 154|app: 0|req: 13/59] 172.17.0.1 () {52 vars in 992 bytes} [Mon Jul 20 14:25:04 2020] GET / => generated 6697 bytes in 16 msecs (HTTP/1.1 200) 4 headers in 137 bytes (1 switches on core 0)
Internal Server Error: /favicon.ico
Traceback (most recent call last):
  File "/usr/local/lib/python3.7/site-packages/django/core/handlers/exception.py", line 34, in inner
    response = get_response(request)
  File "/usr/local/lib/python3.7/site-packages/django/utils/deprecation.py", line 93, in __call__
    response = self.process_request(request)
  File "/usr/local/lib/python3.7/site-packages/django/middleware/common.py", line 53, in process_request
    if self.should_redirect_with_slash(request):
  File "/usr/local/lib/python3.7/site-packages/django/middleware/common.py", line 71, in should_redirect_with_slash
    not is_valid_path(request.path_info, urlconf) and
  File "/usr/local/lib/python3.7/site-packages/django/urls/base.py", line 154, in is_valid_path
    resolve(path, urlconf)
  File "/usr/local/lib/python3.7/site-packages/django/urls/base.py", line 25, in resolve
    return get_resolver(urlconf).resolve(path)
  File "/usr/local/lib/python3.7/site-packages/django/urls/resolvers.py", line 546, in resolve
    sub_match = pattern.resolve(new_path)
  File "/usr/local/lib/python3.7/site-packages/django/urls/resolvers.py", line 546, in resolve
    sub_match = pattern.resolve(new_path)
AttributeError: 'str' object has no attribute 'resolve'
[pid: 155|app: 0|req: 12/60] 172.17.0.1 () {48 vars in 874 bytes} [Mon Jul 20 14:25:04 2020] GET /favicon.ico => generated 75548 bytes in 34 msecs (HTTP/1.1 500) 2 headers in 96 bytes (1 switches on core 0)
[pid: 156|app: 0|req: 13/61] 172.17.0.1 () {52 vars in 992 bytes} [Mon Jul 20 14:25:04 2020] GET / => generated 6697 bytes in 6 msecs (HTTP/1.1 200) 4 headers in 137 bytes (1 switches on core 0)
Internal Server Error: /favicon.ico
Traceback (most recent call last):
  File "/usr/local/lib/python3.7/site-packages/django/core/handlers/exception.py", line 34, in inner
    response = get_response(request)
  File "/usr/local/lib/python3.7/site-packages/django/utils/deprecation.py", line 93, in __call__
    response = self.process_request(request)
  File "/usr/local/lib/python3.7/site-packages/django/middleware/common.py", line 53, in process_request
    if self.should_redirect_with_slash(request):
  File "/usr/local/lib/python3.7/site-packages/django/middleware/common.py", line 71, in should_redirect_with_slash
    not is_valid_path(request.path_info, urlconf) and
  File "/usr/local/lib/python3.7/site-packages/django/urls/base.py", line 154, in is_valid_path
    resolve(path, urlconf)
  File "/usr/local/lib/python3.7/site-packages/django/urls/base.py", line 25, in resolve
    return get_resolver(urlconf).resolve(path)
  File "/usr/local/lib/python3.7/site-packages/django/urls/resolvers.py", line 546, in resolve
    sub_match = pattern.resolve(new_path)
  File "/usr/local/lib/python3.7/site-packages/django/urls/resolvers.py", line 546, in resolve
    sub_match = pattern.resolve(new_path)
AttributeError: 'str' object has no attribute 'resolve'
[pid: 157|app: 0|req: 12/62] 172.17.0.1 () {48 vars in 874 bytes} [Mon Jul 20 14:25:04 2020] GET /favicon.ico => generated 75548 bytes in 37 msecs (HTTP/1.1 500) 2 headers in 96 bytes (1 switches on core 0)
[pid: 158|app: 0|req: 13/63] 172.17.0.1 () {52 vars in 992 bytes} [Mon Jul 20 14:25:05 2020] GET / => generated 6697 bytes in 7 msecs (HTTP/1.1 200) 4 headers in 137 bytes (1 switches on core 0)
Internal Server Error: /favicon.ico
Traceback (most recent call last):
  File "/usr/local/lib/python3.7/site-packages/django/core/handlers/exception.py", line 34, in inner
    response = get_response(request)
  File "/usr/local/lib/python3.7/site-packages/django/utils/deprecation.py", line 93, in __call__
    response = self.process_request(request)
  File "/usr/local/lib/python3.7/site-packages/django/middleware/common.py", line 53, in process_request
    if self.should_redirect_with_slash(request):
  File "/usr/local/lib/python3.7/site-packages/django/middleware/common.py", line 71, in should_redirect_with_slash
    not is_valid_path(request.path_info, urlconf) and
  File "/usr/local/lib/python3.7/site-packages/django/urls/base.py", line 154, in is_valid_path
    resolve(path, urlconf)
  File "/usr/local/lib/python3.7/site-packages/django/urls/base.py", line 25, in resolve
    return get_resolver(urlconf).resolve(path)
  File "/usr/local/lib/python3.7/site-packages/django/urls/resolvers.py", line 546, in resolve
    sub_match = pattern.resolve(new_path)
  File "/usr/local/lib/python3.7/site-packages/django/urls/resolvers.py", line 546, in resolve
    sub_match = pattern.resolve(new_path)
AttributeError: 'str' object has no attribute 'resolve'
[pid: 154|app: 0|req: 14/64] 172.17.0.1 () {48 vars in 874 bytes} [Mon Jul 20 14:25:05 2020] GET /favicon.ico => generated 75548 bytes in 36 msecs (HTTP/1.1 500) 2 headers in 96 bytes (1 switches on core 0)
[pid: 155|app: 0|req: 13/65] 172.17.0.1 () {52 vars in 992 bytes} [Mon Jul 20 14:25:06 2020] GET / => generated 6697 bytes in 6 msecs (HTTP/1.1 200) 4 headers in 137 bytes (1 switches on core 0)
Internal Server Error: /favicon.ico
Traceback (most recent call last):
  File "/usr/local/lib/python3.7/site-packages/django/core/handlers/exception.py", line 34, in inner
    response = get_response(request)
  File "/usr/local/lib/python3.7/site-packages/django/utils/deprecation.py", line 93, in __call__
    response = self.process_request(request)
  File "/usr/local/lib/python3.7/site-packages/django/middleware/common.py", line 53, in process_request
    if self.should_redirect_with_slash(request):
  File "/usr/local/lib/python3.7/site-packages/django/middleware/common.py", line 71, in should_redirect_with_slash
    not is_valid_path(request.path_info, urlconf) and
  File "/usr/local/lib/python3.7/site-packages/django/urls/base.py", line 154, in is_valid_path
    resolve(path, urlconf)
  File "/usr/local/lib/python3.7/site-packages/django/urls/base.py", line 25, in resolve
    return get_resolver(urlconf).resolve(path)
  File "/usr/local/lib/python3.7/site-packages/django/urls/resolvers.py", line 546, in resolve
    sub_match = pattern.resolve(new_path)
  File "/usr/local/lib/python3.7/site-packages/django/urls/resolvers.py", line 546, in resolve
    sub_match = pattern.resolve(new_path)
AttributeError: 'str' object has no attribute 'resolve'
[pid: 156|app: 0|req: 14/66] 172.17.0.1 () {48 vars in 874 bytes} [Mon Jul 20 14:25:06 2020] GET /favicon.ico => generated 75548 bytes in 38 msecs (HTTP/1.1 500) 2 headers in 96 bytes (1 switches on core 0)
[pid: 157|app: 0|req: 13/67] 172.17.0.1 () {52 vars in 992 bytes} [Mon Jul 20 14:25:07 2020] GET / => generated 6697 bytes in 8 msecs (HTTP/1.1 200) 4 headers in 137 bytes (1 switches on core 0)
Internal Server Error: /favicon.ico
Traceback (most recent call last):
  File "/usr/local/lib/python3.7/site-packages/django/core/handlers/exception.py", line 34, in inner
    response = get_response(request)
  File "/usr/local/lib/python3.7/site-packages/django/utils/deprecation.py", line 93, in __call__
    response = self.process_request(request)
  File "/usr/local/lib/python3.7/site-packages/django/middleware/common.py", line 53, in process_request
    if self.should_redirect_with_slash(request):
  File "/usr/local/lib/python3.7/site-packages/django/middleware/common.py", line 71, in should_redirect_with_slash
    not is_valid_path(request.path_info, urlconf) and
  File "/usr/local/lib/python3.7/site-packages/django/urls/base.py", line 154, in is_valid_path
    resolve(path, urlconf)
  File "/usr/local/lib/python3.7/site-packages/django/urls/base.py", line 25, in resolve
    return get_resolver(urlconf).resolve(path)
  File "/usr/local/lib/python3.7/site-packages/django/urls/resolvers.py", line 546, in resolve
    sub_match = pattern.resolve(new_path)
  File "/usr/local/lib/python3.7/site-packages/django/urls/resolvers.py", line 546, in resolve
    sub_match = pattern.resolve(new_path)
AttributeError: 'str' object has no attribute 'resolve'
[pid: 158|app: 0|req: 14/68] 172.17.0.1 () {48 vars in 874 bytes} [Mon Jul 20 14:25:07 2020] GET /favicon.ico => generated 75548 bytes in 36 msecs (HTTP/1.1 500) 2 headers in 96 bytes (1 switches on core 0)
[pid: 154|app: 0|req: 15/69] 172.17.0.1 () {44 vars in 833 bytes} [Mon Jul 20 14:59:55 2020] GET / => generated 6697 bytes in 10 msecs (HTTP/1.1 200) 4 headers in 137 bytes (1 switches on core 0)
Internal Server Error: /favicon.ico
Traceback (most recent call last):
  File "/usr/local/lib/python3.7/site-packages/django/core/handlers/exception.py", line 34, in inner
    response = get_response(request)
  File "/usr/local/lib/python3.7/site-packages/django/utils/deprecation.py", line 93, in __call__
    response = self.process_request(request)
  File "/usr/local/lib/python3.7/site-packages/django/middleware/common.py", line 53, in process_request
    if self.should_redirect_with_slash(request):
  File "/usr/local/lib/python3.7/site-packages/django/middleware/common.py", line 71, in should_redirect_with_slash
    not is_valid_path(request.path_info, urlconf) and
  File "/usr/local/lib/python3.7/site-packages/django/urls/base.py", line 154, in is_valid_path
    resolve(path, urlconf)
  File "/usr/local/lib/python3.7/site-packages/django/urls/base.py", line 25, in resolve
    return get_resolver(urlconf).resolve(path)
  File "/usr/local/lib/python3.7/site-packages/django/urls/resolvers.py", line 546, in resolve
    sub_match = pattern.resolve(new_path)
  File "/usr/local/lib/python3.7/site-packages/django/urls/resolvers.py", line 546, in resolve
    sub_match = pattern.resolve(new_path)
AttributeError: 'str' object has no attribute 'resolve'
[pid: 155|app: 0|req: 14/70] 172.17.0.1 () {42 vars in 740 bytes} [Mon Jul 20 14:59:56 2020] GET /favicon.ico => generated 74928 bytes in 42 msecs (HTTP/1.1 500) 2 headers in 96 bytes (1 switches on core 0)
Internal Server Error: /ajax/epgp
Traceback (most recent call last):
  File "/usr/local/lib/python3.7/site-packages/django/core/handlers/exception.py", line 34, in inner
    response = get_response(request)
  File "/usr/local/lib/python3.7/site-packages/django/utils/deprecation.py", line 93, in __call__
    response = self.process_request(request)
  File "/usr/local/lib/python3.7/site-packages/django/middleware/common.py", line 53, in process_request
    if self.should_redirect_with_slash(request):
  File "/usr/local/lib/python3.7/site-packages/django/middleware/common.py", line 71, in should_redirect_with_slash
    not is_valid_path(request.path_info, urlconf) and
  File "/usr/local/lib/python3.7/site-packages/django/urls/base.py", line 154, in is_valid_path
    resolve(path, urlconf)
  File "/usr/local/lib/python3.7/site-packages/django/urls/base.py", line 25, in resolve
    return get_resolver(urlconf).resolve(path)
  File "/usr/local/lib/python3.7/site-packages/django/urls/resolvers.py", line 546, in resolve
    sub_match = pattern.resolve(new_path)
  File "/usr/local/lib/python3.7/site-packages/django/urls/resolvers.py", line 546, in resolve
    sub_match = pattern.resolve(new_path)
AttributeError: 'str' object has no attribute 'resolve'
[pid: 156|app: 0|req: 15/71] 172.17.0.1 () {44 vars in 813 bytes} [Mon Jul 20 14:59:57 2020] GET /ajax/epgp?_=1595257195978 => generated 12366 bytes in 14 msecs (HTTP/1.1 500) 2 headers in 112 bytes (1 switches on core 0)
Internal Server Error: /ajax/epgploot
Traceback (most recent call last):
  File "/usr/local/lib/python3.7/site-packages/django/core/handlers/exception.py", line 34, in inner
    response = get_response(request)
  File "/usr/local/lib/python3.7/site-packages/django/utils/deprecation.py", line 93, in __call__
    response = self.process_request(request)
  File "/usr/local/lib/python3.7/site-packages/django/middleware/common.py", line 53, in process_request
    if self.should_redirect_with_slash(request):
  File "/usr/local/lib/python3.7/site-packages/django/middleware/common.py", line 71, in should_redirect_with_slash
    not is_valid_path(request.path_info, urlconf) and
  File "/usr/local/lib/python3.7/site-packages/django/urls/base.py", line 154, in is_valid_path
    resolve(path, urlconf)
  File "/usr/local/lib/python3.7/site-packages/django/urls/base.py", line 25, in resolve
    return get_resolver(urlconf).resolve(path)
  File "/usr/local/lib/python3.7/site-packages/django/urls/resolvers.py", line 546, in resolve
    sub_match = pattern.resolve(new_path)
  File "/usr/local/lib/python3.7/site-packages/django/urls/resolvers.py", line 546, in resolve
    sub_match = pattern.resolve(new_path)
AttributeError: 'str' object has no attribute 'resolve'
[pid: 157|app: 0|req: 14/72] 172.17.0.1 () {44 vars in 821 bytes} [Mon Jul 20 15:00:00 2020] GET /ajax/epgploot?_=1595257195979 => generated 12386 bytes in 13 msecs (HTTP/1.1 500) 2 headers in 112 bytes (1 switches on core 0)
Internal Server Error: /ajax/epgpaddlog
Traceback (most recent call last):
  File "/usr/local/lib/python3.7/site-packages/django/core/handlers/exception.py", line 34, in inner
    response = get_response(request)
  File "/usr/local/lib/python3.7/site-packages/django/utils/deprecation.py", line 93, in __call__
    response = self.process_request(request)
  File "/usr/local/lib/python3.7/site-packages/django/middleware/common.py", line 53, in process_request
    if self.should_redirect_with_slash(request):
  File "/usr/local/lib/python3.7/site-packages/django/middleware/common.py", line 71, in should_redirect_with_slash
    not is_valid_path(request.path_info, urlconf) and
  File "/usr/local/lib/python3.7/site-packages/django/urls/base.py", line 154, in is_valid_path
    resolve(path, urlconf)
  File "/usr/local/lib/python3.7/site-packages/django/urls/base.py", line 25, in resolve
    return get_resolver(urlconf).resolve(path)
  File "/usr/local/lib/python3.7/site-packages/django/urls/resolvers.py", line 546, in resolve
    sub_match = pattern.resolve(new_path)
  File "/usr/local/lib/python3.7/site-packages/django/urls/resolvers.py", line 546, in resolve
    sub_match = pattern.resolve(new_path)
AttributeError: 'str' object has no attribute 'resolve'
[pid: 158|app: 0|req: 15/73] 172.17.0.1 () {44 vars in 825 bytes} [Mon Jul 20 15:00:01 2020] GET /ajax/epgpaddlog?_=1595257195980 => generated 12396 bytes in 14 msecs (HTTP/1.1 500) 2 headers in 112 bytes (1 switches on core 0)
SIGINT/SIGQUIT received...killing workers...
worker 1 buried after 1 seconds
worker 2 buried after 1 seconds
worker 3 buried after 1 seconds
worker 4 buried after 1 seconds
worker 5 buried after 1 seconds
goodbye to uWSGI.
VACUUM: pidfile removed.
*** Starting uWSGI 2.0.19.1 (64bit) on [Mon Jul 20 15:00:07 2020] ***
compiled with version: 8.3.0 on 20 July 2020 10:00:56
os: Linux-4.19.76-linuxkit #1 SMP Tue May 26 11:42:35 UTC 2020
nodename: 5d70340e2b94
machine: x86_64
clock source: unix
pcre jit disabled
detected number of CPU cores: 2
current working directory: /home/ares
writing pidfile to /home/ares/log/uwsgi.pid
detected binary path: /usr/local/bin/uwsgi
*** WARNING: you are running uWSGI as root !!! (use the --uid flag) *** 
chdir() to /home/ares
your memory page size is 4096 bytes
detected max file descriptor number: 1048576
lock engine: pthread robust mutexes
thunder lock: enabled
uwsgi socket 0 bound to TCP address 0.0.0.0:8000 fd 3
*** WARNING: you are running uWSGI as root !!! (use the --uid flag) *** 
Python version: 3.7.8 (default, Jun 30 2020, 18:27:23)  [GCC 8.3.0]
Python main interpreter initialized at 0x56044d490410
*** WARNING: you are running uWSGI as root !!! (use the --uid flag) *** 
python threads support enabled
your server socket listen backlog is limited to 100 connections
your mercy for graceful operations on workers is 60 seconds
mapped 658704 bytes (643 KB) for 5 cores
*** Operational MODE: preforking ***
WSGI app 0 (mountpoint='') ready in 1 seconds on interpreter 0x56044d490410 pid: 162 (default app)
*** WARNING: you are running uWSGI as root !!! (use the --uid flag) *** 
*** uWSGI is running in multiple interpreter mode ***
spawned uWSGI master process (pid: 162)
spawned uWSGI worker 1 (pid: 163, cores: 1)
spawned uWSGI worker 2 (pid: 164, cores: 1)
spawned uWSGI worker 3 (pid: 165, cores: 1)
spawned uWSGI worker 4 (pid: 166, cores: 1)
spawned uWSGI worker 5 (pid: 167, cores: 1)
[pid: 163|app: 0|req: 1/1] 172.17.0.1 () {44 vars in 833 bytes} [Mon Jul 20 15:00:10 2020] GET / => generated 6697 bytes in 59 msecs (HTTP/1.1 200) 4 headers in 137 bytes (1 switches on core 0)
Not Found: /favicon.ico
[pid: 164|app: 0|req: 1/2] 172.17.0.1 () {42 vars in 740 bytes} [Mon Jul 20 15:00:10 2020] GET /favicon.ico => generated 2286 bytes in 21 msecs (HTTP/1.1 404) 4 headers in 129 bytes (1 switches on core 0)
[pid: 165|app: 0|req: 1/3] 172.17.0.1 () {44 vars in 813 bytes} [Mon Jul 20 15:00:12 2020] GET /ajax/epgp?_=1595257210894 => generated 0 bytes in 13 msecs (HTTP/1.1 301) 4 headers in 165 bytes (1 switches on core 0)
[pid: 166|app: 0|req: 1/4] 172.17.0.1 () {44 vars in 815 bytes} [Mon Jul 20 15:00:12 2020] GET /ajax/epgp/?_=1595257210894 => generated 110 bytes in 20 msecs (HTTP/1.1 200) 4 headers in 136 bytes (1 switches on core 0)
[pid: 167|app: 0|req: 1/5] 172.17.0.1 () {44 vars in 821 bytes} [Mon Jul 20 15:00:12 2020] GET /ajax/epgploot?_=1595257210895 => generated 0 bytes in 9 msecs (HTTP/1.1 301) 4 headers in 169 bytes (1 switches on core 0)
[pid: 163|app: 0|req: 2/6] 172.17.0.1 () {44 vars in 823 bytes} [Mon Jul 20 15:00:12 2020] GET /ajax/epgploot/?_=1595257210895 => generated 12 bytes in 10 msecs (HTTP/1.1 200) 4 headers in 135 bytes (1 switches on core 0)
[pid: 164|app: 0|req: 2/7] 172.17.0.1 () {44 vars in 825 bytes} [Mon Jul 20 15:00:13 2020] GET /ajax/epgpaddlog?_=1595257210896 => generated 0 bytes in 1 msecs (HTTP/1.1 301) 4 headers in 171 bytes (1 switches on core 0)
[pid: 165|app: 0|req: 2/8] 172.17.0.1 () {44 vars in 827 bytes} [Mon Jul 20 15:00:13 2020] GET /ajax/epgpaddlog/?_=1595257210896 => generated 12 bytes in 18 msecs (HTTP/1.1 200) 4 headers in 135 bytes (1 switches on core 0)
[pid: 166|app: 0|req: 2/9] 172.17.0.1 () {44 vars in 833 bytes} [Mon Jul 20 15:02:06 2020] GET / => generated 6697 bytes in 22 msecs (HTTP/1.1 200) 4 headers in 137 bytes (1 switches on core 0)
[pid: 167|app: 0|req: 2/10] 172.17.0.1 () {44 vars in 853 bytes} [Mon Jul 20 15:07:27 2020] GET /ajax/epgp/ => generated 110 bytes in 16 msecs (HTTP/1.1 200) 4 headers in 136 bytes (1 switches on core 0)
uwsgi_proto_uwsgi_parser(): Success [proto/uwsgi.c line 40]
*** Starting uWSGI 2.0.19.1 (64bit) on [Tue Jul 21 04:48:17 2020] ***
compiled with version: 8.3.0 on 20 July 2020 10:00:56
os: Linux-4.19.76-linuxkit #1 SMP Tue May 26 11:42:35 UTC 2020
nodename: 5d70340e2b94
machine: x86_64
clock source: unix
pcre jit disabled
detected number of CPU cores: 2
current working directory: /home/ares
writing pidfile to /home/ares/log/uwsgi.pid
detected binary path: /usr/local/bin/uwsgi
*** WARNING: you are running uWSGI as root !!! (use the --uid flag) *** 
chdir() to /home/ares
your memory page size is 4096 bytes
detected max file descriptor number: 1048576
lock engine: pthread robust mutexes
thunder lock: enabled
uwsgi socket 0 bound to TCP address 0.0.0.0:8000 fd 3
*** WARNING: you are running uWSGI as root !!! (use the --uid flag) *** 
Python version: 3.7.8 (default, Jun 30 2020, 18:27:23)  [GCC 8.3.0]
Python main interpreter initialized at 0x563f39be6350
*** WARNING: you are running uWSGI as root !!! (use the --uid flag) *** 
python threads support enabled
your server socket listen backlog is limited to 100 connections
your mercy for graceful operations on workers is 60 seconds
mapped 658704 bytes (643 KB) for 5 cores
*** Operational MODE: preforking ***
WSGI app 0 (mountpoint='') ready in 0 seconds on interpreter 0x563f39be6350 pid: 25 (default app)
*** WARNING: you are running uWSGI as root !!! (use the --uid flag) *** 
*** uWSGI is running in multiple interpreter mode ***
spawned uWSGI master process (pid: 25)
spawned uWSGI worker 1 (pid: 26, cores: 1)
spawned uWSGI worker 2 (pid: 27, cores: 1)
spawned uWSGI worker 3 (pid: 28, cores: 1)
spawned uWSGI worker 4 (pid: 29, cores: 1)
spawned uWSGI worker 5 (pid: 30, cores: 1)
[pid: 26|app: 0|req: 1/1] 172.17.0.1 () {52 vars in 992 bytes} [Tue Jul 21 04:48:19 2020] GET / => generated 6605 bytes in 70 msecs (HTTP/1.1 200) 4 headers in 137 bytes (1 switches on core 0)
[pid: 27|app: 0|req: 1/2] 172.17.0.1 () {50 vars in 944 bytes} [Tue Jul 21 04:48:19 2020] GET /ajax/epgp?_=1595306899701 => generated 0 bytes in 15 msecs (HTTP/1.1 301) 4 headers in 165 bytes (1 switches on core 0)
Not Found: /favicon.ico
[pid: 29|app: 0|req: 1/3] 172.17.0.1 () {48 vars in 874 bytes} [Tue Jul 21 04:48:19 2020] GET /favicon.ico => generated 2283 bytes in 26 msecs (HTTP/1.1 404) 4 headers in 129 bytes (1 switches on core 0)
[pid: 28|app: 0|req: 1/4] 172.17.0.1 () {50 vars in 946 bytes} [Tue Jul 21 04:48:19 2020] GET /ajax/epgp/?_=1595306899701 => generated 12 bytes in 32 msecs (HTTP/1.1 200) 4 headers in 135 bytes (1 switches on core 0)
[pid: 30|app: 0|req: 1/5] 172.17.0.1 () {50 vars in 952 bytes} [Tue Jul 21 04:48:23 2020] GET /ajax/epgploot?_=1595306899702 => generated 0 bytes in 9 msecs (HTTP/1.1 301) 4 headers in 169 bytes (1 switches on core 0)
[pid: 26|app: 0|req: 2/6] 172.17.0.1 () {50 vars in 954 bytes} [Tue Jul 21 04:48:23 2020] GET /ajax/epgploot/?_=1595306899702 => generated 12 bytes in 9 msecs (HTTP/1.1 200) 4 headers in 135 bytes (1 switches on core 0)
[pid: 27|app: 0|req: 2/7] 172.17.0.1 () {50 vars in 956 bytes} [Tue Jul 21 04:48:23 2020] GET /ajax/epgpaddlog?_=1595306899703 => generated 0 bytes in 0 msecs (HTTP/1.1 301) 4 headers in 171 bytes (1 switches on core 0)
[pid: 29|app: 0|req: 2/8] 172.17.0.1 () {50 vars in 958 bytes} [Tue Jul 21 04:48:23 2020] GET /ajax/epgpaddlog/?_=1595306899703 => generated 12 bytes in 17 msecs (HTTP/1.1 200) 4 headers in 135 bytes (1 switches on core 0)
[pid: 28|app: 0|req: 2/9] 172.17.0.1 () {52 vars in 992 bytes} [Tue Jul 21 04:48:26 2020] GET / => generated 6605 bytes in 16 msecs (HTTP/1.1 200) 4 headers in 137 bytes (1 switches on core 0)
[pid: 30|app: 0|req: 2/10] 172.17.0.1 () {50 vars in 944 bytes} [Tue Jul 21 04:48:26 2020] GET /ajax/epgp?_=1595306906844 => generated 0 bytes in 0 msecs (HTTP/1.1 301) 4 headers in 165 bytes (1 switches on core 0)
[pid: 26|app: 0|req: 3/11] 172.17.0.1 () {50 vars in 946 bytes} [Tue Jul 21 04:48:26 2020] GET /ajax/epgp/?_=1595306906844 => generated 12 bytes in 6 msecs (HTTP/1.1 200) 4 headers in 135 bytes (1 switches on core 0)
[pid: 27|app: 0|req: 3/12] 172.17.0.1 () {50 vars in 952 bytes} [Tue Jul 21 04:48:30 2020] GET /ajax/epgploot?_=1595306906845 => generated 0 bytes in 0 msecs (HTTP/1.1 301) 4 headers in 169 bytes (1 switches on core 0)
[pid: 29|app: 0|req: 3/13] 172.17.0.1 () {50 vars in 954 bytes} [Tue Jul 21 04:48:30 2020] GET /ajax/epgploot/?_=1595306906845 => generated 12 bytes in 6 msecs (HTTP/1.1 200) 4 headers in 135 bytes (1 switches on core 0)
[pid: 28|app: 0|req: 3/14] 172.17.0.1 () {50 vars in 956 bytes} [Tue Jul 21 04:48:31 2020] GET /ajax/epgpaddlog?_=1595306906846 => generated 0 bytes in 1 msecs (HTTP/1.1 301) 4 headers in 171 bytes (1 switches on core 0)
[pid: 30|app: 0|req: 3/15] 172.17.0.1 () {50 vars in 958 bytes} [Tue Jul 21 04:48:31 2020] GET /ajax/epgpaddlog/?_=1595306906846 => generated 12 bytes in 27 msecs (HTTP/1.1 200) 4 headers in 135 bytes (1 switches on core 0)
Not Found: /announce.php
[pid: 26|app: 0|req: 4/16] 172.17.0.1 () {34 vars in 834 bytes} [Tue Jul 21 04:53:44 2020] GET /announce.php?info_hash=%A1j%0A%F9%A0%ADLg%B6%F5%18%5E%19%A4%2B%B3B%F6Q3&peer_id=-XL0012-%F6%CA%B1%9A%88L%D4%C8%02%22h%8A&ip=192.168.0.2&port=15000&uploaded=0&downloaded=0&left=1351133152&numwant=200&key=6285&compact=1&event=started => generated 2557 bytes in 5 msecs (HTTP/1.0 404) 4 headers in 129 bytes (1 switches on core 0)
Not Found: /announce.php
[pid: 27|app: 0|req: 4/17] 172.17.0.1 () {34 vars in 834 bytes} [Tue Jul 21 04:53:44 2020] GET /announce.php?info_hash=%A1j%0A%F9%A0%ADLg%B6%F5%18%5E%19%A4%2B%B3B%F6Q3&peer_id=-XL0012-%F6%CA%B1%9A%88L%D4%C8%02%22h%8A&ip=192.168.0.2&port=15000&uploaded=0&downloaded=0&left=1351133152&numwant=200&key=6471&compact=1&event=started => generated 2557 bytes in 7 msecs (HTTP/1.0 404) 4 headers in 129 bytes (1 switches on core 0)
*** Starting uWSGI 2.0.19.1 (64bit) on [Mon Jul 27 03:16:32 2020] ***
compiled with version: 8.3.0 on 20 July 2020 10:00:56
os: Linux-4.19.76-linuxkit #1 SMP Tue May 26 11:42:35 UTC 2020
nodename: 5d70340e2b94
machine: x86_64
clock source: unix
pcre jit disabled
detected number of CPU cores: 2
current working directory: /home/ares
writing pidfile to /home/ares/log/uwsgi.pid
detected binary path: /usr/local/bin/uwsgi
*** WARNING: you are running uWSGI as root !!! (use the --uid flag) *** 
chdir() to /home/ares
your memory page size is 4096 bytes
detected max file descriptor number: 1048576
lock engine: pthread robust mutexes
thunder lock: enabled
uwsgi socket 0 bound to TCP address 0.0.0.0:8000 fd 3
*** WARNING: you are running uWSGI as root !!! (use the --uid flag) *** 
Python version: 3.7.8 (default, Jun 30 2020, 18:27:23)  [GCC 8.3.0]
Python main interpreter initialized at 0x55f15a5f5390
*** WARNING: you are running uWSGI as root !!! (use the --uid flag) *** 
python threads support enabled
your server socket listen backlog is limited to 100 connections
your mercy for graceful operations on workers is 60 seconds
mapped 658704 bytes (643 KB) for 5 cores
*** Operational MODE: preforking ***
WSGI app 0 (mountpoint='') ready in 1 seconds on interpreter 0x55f15a5f5390 pid: 19 (default app)
*** WARNING: you are running uWSGI as root !!! (use the --uid flag) *** 
*** uWSGI is running in multiple interpreter mode ***
spawned uWSGI master process (pid: 19)
spawned uWSGI worker 1 (pid: 20, cores: 1)
spawned uWSGI worker 2 (pid: 21, cores: 1)
spawned uWSGI worker 3 (pid: 22, cores: 1)
spawned uWSGI worker 4 (pid: 23, cores: 1)
spawned uWSGI worker 5 (pid: 24, cores: 1)
[pid: 20|app: 0|req: 1/1] 172.17.0.1 () {42 vars in 745 bytes} [Mon Jul 27 03:16:35 2020] GET / => generated 6605 bytes in 86 msecs (HTTP/1.1 200) 4 headers in 137 bytes (1 switches on core 0)
[pid: 21|app: 0|req: 1/2] 172.17.0.1 () {42 vars in 726 bytes} [Mon Jul 27 03:16:36 2020] GET /ajax/epgp?_=1595819795404 => generated 0 bytes in 20 msecs (HTTP/1.1 301) 4 headers in 165 bytes (1 switches on core 0)
Not Found: /favicon.ico
[pid: 22|app: 0|req: 1/3] 172.17.0.1 () {40 vars in 653 bytes} [Mon Jul 27 03:16:36 2020] GET /favicon.ico => generated 2287 bytes in 29 msecs (HTTP/1.1 404) 4 headers in 129 bytes (1 switches on core 0)
[pid: 23|app: 0|req: 1/4] 172.17.0.1 () {42 vars in 728 bytes} [Mon Jul 27 03:16:36 2020] GET /ajax/epgp/?_=1595819795404 => generated 12 bytes in 23 msecs (HTTP/1.1 200) 4 headers in 135 bytes (1 switches on core 0)
[pid: 24|app: 0|req: 1/5] 172.17.0.1 () {42 vars in 745 bytes} [Mon Jul 27 03:17:12 2020] GET / => generated 6721 bytes in 45 msecs (HTTP/1.1 200) 4 headers in 137 bytes (1 switches on core 0)
[pid: 20|app: 0|req: 2/6] 172.17.0.1 () {42 vars in 726 bytes} [Mon Jul 27 03:17:12 2020] GET /ajax/epgp?_=1595819832099 => generated 0 bytes in 1 msecs (HTTP/1.1 301) 4 headers in 165 bytes (1 switches on core 0)
[pid: 21|app: 0|req: 2/7] 172.17.0.1 () {42 vars in 728 bytes} [Mon Jul 27 03:17:12 2020] GET /ajax/epgp/?_=1595819832099 => generated 12 bytes in 12 msecs (HTTP/1.1 200) 4 headers in 135 bytes (1 switches on core 0)
[pid: 22|app: 0|req: 2/8] 172.17.0.1 () {42 vars in 745 bytes} [Mon Jul 27 03:17:16 2020] GET / => generated 6721 bytes in 22 msecs (HTTP/1.1 200) 4 headers in 137 bytes (1 switches on core 0)
[pid: 23|app: 0|req: 2/9] 172.17.0.1 () {42 vars in 726 bytes} [Mon Jul 27 03:17:16 2020] GET /ajax/epgp?_=1595819836174 => generated 0 bytes in 1 msecs (HTTP/1.1 301) 4 headers in 165 bytes (1 switches on core 0)
[pid: 24|app: 0|req: 2/10] 172.17.0.1 () {42 vars in 728 bytes} [Mon Jul 27 03:17:16 2020] GET /ajax/epgp/?_=1595819836174 => generated 12 bytes in 7 msecs (HTTP/1.1 200) 4 headers in 135 bytes (1 switches on core 0)
*** Starting uWSGI 2.0.19.1 (64bit) on [Tue Aug  4 07:50:07 2020] ***
compiled with version: 8.3.0 on 20 July 2020 10:00:56
os: Linux-4.19.76-linuxkit #1 SMP Tue May 26 11:42:35 UTC 2020
nodename: 5d70340e2b94
machine: x86_64
clock source: unix
pcre jit disabled
detected number of CPU cores: 2
current working directory: /home/ares
writing pidfile to /home/ares/log/uwsgi.pid
detected binary path: /usr/local/bin/uwsgi
*** WARNING: you are running uWSGI as root !!! (use the --uid flag) *** 
chdir() to /home/ares
your memory page size is 4096 bytes
detected max file descriptor number: 1048576
lock engine: pthread robust mutexes
thunder lock: enabled
uwsgi socket 0 bound to TCP address 0.0.0.0:8000 fd 3
*** WARNING: you are running uWSGI as root !!! (use the --uid flag) *** 
Python version: 3.7.8 (default, Jun 30 2020, 18:27:23)  [GCC 8.3.0]
Python main interpreter initialized at 0x55ec3bc16390
*** WARNING: you are running uWSGI as root !!! (use the --uid flag) *** 
python threads support enabled
your server socket listen backlog is limited to 100 connections
your mercy for graceful operations on workers is 60 seconds
mapped 658704 bytes (643 KB) for 5 cores
*** Operational MODE: preforking ***
WSGI app 0 (mountpoint='') ready in 1 seconds on interpreter 0x55ec3bc16390 pid: 20 (default app)
*** WARNING: you are running uWSGI as root !!! (use the --uid flag) *** 
*** uWSGI is running in multiple interpreter mode ***
spawned uWSGI master process (pid: 20)
spawned uWSGI worker 1 (pid: 21, cores: 1)
spawned uWSGI worker 2 (pid: 22, cores: 1)
spawned uWSGI worker 3 (pid: 23, cores: 1)
spawned uWSGI worker 4 (pid: 24, cores: 1)
spawned uWSGI worker 5 (pid: 25, cores: 1)
Internal Server Error: /
Traceback (most recent call last):
  File "/usr/local/lib/python3.7/site-packages/django/core/handlers/exception.py", line 34, in inner
    response = get_response(request)
  File "/usr/local/lib/python3.7/site-packages/django/core/handlers/base.py", line 115, in _get_response
    response = self.process_exception_by_middleware(e, request)
  File "/usr/local/lib/python3.7/site-packages/django/core/handlers/base.py", line 113, in _get_response
    response = wrapped_callback(request, *callback_args, **callback_kwargs)
  File "./point/views.py", line 7, in index
    dkp = DKPtable.objects.all()
NameError: name 'DKPtable' is not defined
[pid: 21|app: 0|req: 1/1] 172.17.0.1 () {52 vars in 979 bytes} [Tue Aug  4 07:50:11 2020] GET / => generated 59343 bytes in 88 msecs (HTTP/1.1 500) 5 headers in 156 bytes (1 switches on core 0)
Not Found: /favicon.ico
[pid: 22|app: 0|req: 1/2] 172.17.0.1 () {48 vars in 861 bytes} [Tue Aug  4 07:50:11 2020] GET /favicon.ico => generated 2283 bytes in 21 msecs (HTTP/1.1 404) 4 headers in 129 bytes (1 switches on core 0)
Internal Server Error: /
Traceback (most recent call last):
  File "/usr/local/lib/python3.7/site-packages/django/core/handlers/exception.py", line 34, in inner
    response = get_response(request)
  File "/usr/local/lib/python3.7/site-packages/django/core/handlers/base.py", line 115, in _get_response
    response = self.process_exception_by_middleware(e, request)
  File "/usr/local/lib/python3.7/site-packages/django/core/handlers/base.py", line 113, in _get_response
    response = wrapped_callback(request, *callback_args, **callback_kwargs)
  File "./point/views.py", line 7, in index
    dkp = DKPtable.objects.all()
NameError: name 'DKPtable' is not defined
[pid: 23|app: 0|req: 1/3] 172.17.0.1 () {52 vars in 979 bytes} [Tue Aug  4 07:50:12 2020] GET / => generated 59343 bytes in 64 msecs (HTTP/1.1 500) 5 headers in 156 bytes (1 switches on core 0)
[pid: 24|app: 0|req: 1/4] 172.17.0.1 () {52 vars in 979 bytes} [Tue Aug  4 07:50:51 2020] GET / => generated 6663 bytes in 59 msecs (HTTP/1.1 200) 4 headers in 137 bytes (1 switches on core 0)
[pid: 25|app: 0|req: 1/5] 172.17.0.1 () {50 vars in 931 bytes} [Tue Aug  4 07:50:54 2020] GET /ajax/epgp?_=1596527454146 => generated 0 bytes in 12 msecs (HTTP/1.1 301) 4 headers in 165 bytes (1 switches on core 0)
[pid: 21|app: 0|req: 2/6] 172.17.0.1 () {50 vars in 933 bytes} [Tue Aug  4 07:50:54 2020] GET /ajax/epgp/?_=1596527454146 => generated 5331 bytes in 9 msecs (HTTP/1.1 200) 4 headers in 137 bytes (1 switches on core 0)
[pid: 22|app: 0|req: 2/7] 172.17.0.1 () {50 vars in 939 bytes} [Tue Aug  4 07:50:59 2020] GET /ajax/epgploot?_=1596527454147 => generated 0 bytes in 0 msecs (HTTP/1.1 301) 4 headers in 169 bytes (1 switches on core 0)
Internal Server Error: /ajax/epgploot/
Traceback (most recent call last):
  File "/usr/local/lib/python3.7/site-packages/django/core/handlers/exception.py", line 34, in inner
    response = get_response(request)
  File "/usr/local/lib/python3.7/site-packages/django/core/handlers/base.py", line 115, in _get_response
    response = self.process_exception_by_middleware(e, request)
  File "/usr/local/lib/python3.7/site-packages/django/core/handlers/base.py", line 113, in _get_response
    response = wrapped_callback(request, *callback_args, **callback_kwargs)
  File "./point/views.py", line 34, in ajax
    json_dict["class"] = models.playerEPGP.objects.get(name=i.name).job
  File "/usr/local/lib/python3.7/site-packages/django/db/models/manager.py", line 82, in manager_method
    return getattr(self.get_queryset(), name)(*args, **kwargs)
  File "/usr/local/lib/python3.7/site-packages/django/db/models/query.py", line 417, in get
    self.model._meta.object_name
point.models.playerEPGP.DoesNotExist: playerEPGP matching query does not exist.
[pid: 23|app: 0|req: 2/8] 172.17.0.1 () {50 vars in 941 bytes} [Tue Aug  4 07:50:59 2020] GET /ajax/epgploot/?_=1596527454147 => generated 12350 bytes in 43 msecs (HTTP/1.1 500) 5 headers in 172 bytes (1 switches on core 0)
[pid: 24|app: 0|req: 2/9] 172.17.0.1 () {50 vars in 943 bytes} [Tue Aug  4 07:51:04 2020] GET /ajax/epgpaddlog?_=1596527454148 => generated 0 bytes in 1 msecs (HTTP/1.1 301) 4 headers in 171 bytes (1 switches on core 0)
[pid: 25|app: 0|req: 2/10] 172.17.0.1 () {50 vars in 945 bytes} [Tue Aug  4 07:51:04 2020] GET /ajax/epgpaddlog/?_=1596527454148 => generated 12 bytes in 12 msecs (HTTP/1.1 200) 4 headers in 135 bytes (1 switches on core 0)
[pid: 21|app: 0|req: 3/11] 172.17.0.1 () {50 vars in 947 bytes} [Tue Aug  4 07:51:07 2020] GET /ajax/dkp?belong=1&_=1596527454149 => generated 0 bytes in 0 msecs (HTTP/1.1 301) 4 headers in 173 bytes (1 switches on core 0)
[pid: 22|app: 0|req: 3/12] 172.17.0.1 () {50 vars in 949 bytes} [Tue Aug  4 07:51:07 2020] GET /ajax/dkp/?belong=1&_=1596527454149 => generated 4160 bytes in 10 msecs (HTTP/1.1 200) 4 headers in 137 bytes (1 switches on core 0)
[pid: 23|app: 0|req: 3/13] 172.17.0.1 () {50 vars in 947 bytes} [Tue Aug  4 07:51:08 2020] GET /ajax/dkp?belong=1&_=1596527454150 => generated 0 bytes in 1 msecs (HTTP/1.1 301) 4 headers in 173 bytes (1 switches on core 0)
[pid: 24|app: 0|req: 3/14] 172.17.0.1 () {50 vars in 949 bytes} [Tue Aug  4 07:51:08 2020] GET /ajax/dkp/?belong=1&_=1596527454150 => generated 4160 bytes in 6 msecs (HTTP/1.1 200) 4 headers in 137 bytes (1 switches on core 0)
[pid: 25|app: 0|req: 3/15] 172.17.0.1 () {50 vars in 947 bytes} [Tue Aug  4 07:51:11 2020] GET /ajax/dkp?belong=1&_=1596527454151 => generated 0 bytes in 0 msecs (HTTP/1.1 301) 4 headers in 173 bytes (1 switches on core 0)
[pid: 21|app: 0|req: 4/16] 172.17.0.1 () {50 vars in 949 bytes} [Tue Aug  4 07:51:11 2020] GET /ajax/dkp/?belong=1&_=1596527454151 => generated 4160 bytes in 6 msecs (HTTP/1.1 200) 4 headers in 137 bytes (1 switches on core 0)
Internal Server Error: /
Traceback (most recent call last):
  File "/usr/local/lib/python3.7/site-packages/django/core/handlers/exception.py", line 34, in inner
    response = get_response(request)
  File "/usr/local/lib/python3.7/site-packages/django/core/handlers/base.py", line 115, in _get_response
    response = self.process_exception_by_middleware(e, request)
  File "/usr/local/lib/python3.7/site-packages/django/core/handlers/base.py", line 113, in _get_response
    response = wrapped_callback(request, *callback_args, **callback_kwargs)
  File "./point/views.py", line 7, in index
    dkp = models.DKPtable.objects.all()
NameError: name 'DKPtable' is not defined
[pid: 22|app: 0|req: 4/17] 172.17.0.1 () {52 vars in 979 bytes} [Tue Aug  4 07:51:23 2020] GET / => generated 59357 bytes in 53 msecs (HTTP/1.1 500) 5 headers in 156 bytes (1 switches on core 0)
Internal Server Error: /
Traceback (most recent call last):
  File "/usr/local/lib/python3.7/site-packages/django/core/handlers/exception.py", line 34, in inner
    response = get_response(request)
  File "/usr/local/lib/python3.7/site-packages/django/core/handlers/base.py", line 115, in _get_response
    response = self.process_exception_by_middleware(e, request)
  File "/usr/local/lib/python3.7/site-packages/django/core/handlers/base.py", line 113, in _get_response
    response = wrapped_callback(request, *callback_args, **callback_kwargs)
  File "./point/views.py", line 7, in index
    dkp = models.DKPtable.objects.all()
NameError: name 'DKPtable' is not defined
[pid: 23|app: 0|req: 4/18] 172.17.0.1 () {52 vars in 979 bytes} [Tue Aug  4 07:51:24 2020] GET / => generated 59357 bytes in 38 msecs (HTTP/1.1 500) 5 headers in 156 bytes (1 switches on core 0)
[pid: 24|app: 0|req: 4/19] 172.17.0.1 () {52 vars in 979 bytes} [Tue Aug  4 07:51:25 2020] GET / => generated 6663 bytes in 8 msecs (HTTP/1.1 200) 4 headers in 137 bytes (1 switches on core 0)
[pid: 25|app: 0|req: 4/20] 172.17.0.1 () {50 vars in 931 bytes} [Tue Aug  4 07:51:25 2020] GET /ajax/epgp?_=1596527485846 => generated 0 bytes in 0 msecs (HTTP/1.1 301) 4 headers in 165 bytes (1 switches on core 0)
[pid: 21|app: 0|req: 5/21] 172.17.0.1 () {50 vars in 933 bytes} [Tue Aug  4 07:51:25 2020] GET /ajax/epgp/?_=1596527485846 => generated 5331 bytes in 8 msecs (HTTP/1.1 200) 4 headers in 137 bytes (1 switches on core 0)
[pid: 22|app: 0|req: 5/22] 172.17.0.1 () {50 vars in 939 bytes} [Tue Aug  4 07:51:28 2020] GET /ajax/epgploot?_=1596527485847 => generated 0 bytes in 0 msecs (HTTP/1.1 301) 4 headers in 169 bytes (1 switches on core 0)
Internal Server Error: /ajax/epgploot/
Traceback (most recent call last):
  File "/usr/local/lib/python3.7/site-packages/django/core/handlers/exception.py", line 34, in inner
    response = get_response(request)
  File "/usr/local/lib/python3.7/site-packages/django/core/handlers/base.py", line 115, in _get_response
    response = self.process_exception_by_middleware(e, request)
  File "/usr/local/lib/python3.7/site-packages/django/core/handlers/base.py", line 113, in _get_response
    response = wrapped_callback(request, *callback_args, **callback_kwargs)
  File "./point/views.py", line 34, in ajax
    json_dict["class"] = models.playerEPGP.objects.get(name=i.name).job
  File "/usr/local/lib/python3.7/site-packages/django/db/models/manager.py", line 82, in manager_method
    return getattr(self.get_queryset(), name)(*args, **kwargs)
  File "/usr/local/lib/python3.7/site-packages/django/db/models/query.py", line 417, in get
    self.model._meta.object_name
point.models.playerEPGP.DoesNotExist: playerEPGP matching query does not exist.
[pid: 23|app: 0|req: 5/23] 172.17.0.1 () {50 vars in 941 bytes} [Tue Aug  4 07:51:28 2020] GET /ajax/epgploot/?_=1596527485847 => generated 12350 bytes in 42 msecs (HTTP/1.1 500) 5 headers in 172 bytes (1 switches on core 0)
Internal Server Error: /ajax/epgploot/
Traceback (most recent call last):
  File "/usr/local/lib/python3.7/site-packages/django/core/handlers/exception.py", line 34, in inner
    response = get_response(request)
  File "/usr/local/lib/python3.7/site-packages/django/core/handlers/base.py", line 115, in _get_response
    response = self.process_exception_by_middleware(e, request)
  File "/usr/local/lib/python3.7/site-packages/django/core/handlers/base.py", line 113, in _get_response
    response = wrapped_callback(request, *callback_args, **callback_kwargs)
  File "./point/views.py", line 34, in ajax
    json_dict["class"] = models.playerEPGP.objects.get(name=i.name).job
  File "/usr/local/lib/python3.7/site-packages/django/db/models/manager.py", line 82, in manager_method
    return getattr(self.get_queryset(), name)(*args, **kwargs)
  File "/usr/local/lib/python3.7/site-packages/django/db/models/query.py", line 417, in get
    self.model._meta.object_name
point.models.playerEPGP.DoesNotExist: playerEPGP matching query does not exist.
[pid: 24|app: 0|req: 5/24] 172.17.0.1 () {48 vars in 982 bytes} [Tue Aug  4 07:51:43 2020] GET /ajax/epgploot/?_=1596527485847 => generated 73335 bytes in 86 msecs (HTTP/1.1 500) 5 headers in 156 bytes (1 switches on core 0)
Internal Server Error: /ajax/epgploot/
Traceback (most recent call last):
  File "/usr/local/lib/python3.7/site-packages/django/core/handlers/exception.py", line 34, in inner
    response = get_response(request)
  File "/usr/local/lib/python3.7/site-packages/django/core/handlers/base.py", line 115, in _get_response
    response = self.process_exception_by_middleware(e, request)
  File "/usr/local/lib/python3.7/site-packages/django/core/handlers/base.py", line 113, in _get_response
    response = wrapped_callback(request, *callback_args, **callback_kwargs)
  File "./point/views.py", line 34, in ajax
    json_dict["class"] = models.playerEPGP.objects.get(name=i.name).job
  File "/usr/local/lib/python3.7/site-packages/django/db/models/manager.py", line 82, in manager_method
    return getattr(self.get_queryset(), name)(*args, **kwargs)
  File "/usr/local/lib/python3.7/site-packages/django/db/models/query.py", line 417, in get
    self.model._meta.object_name
point.models.playerEPGP.DoesNotExist: playerEPGP matching query does not exist.
[pid: 25|app: 0|req: 5/25] 172.17.0.1 () {50 vars in 976 bytes} [Tue Aug  4 07:51:53 2020] GET /ajax/epgploot/ => generated 73044 bytes in 78 msecs (HTTP/1.1 500) 5 headers in 156 bytes (1 switches on core 0)
Internal Server Error: /ajax/epgploot/
Traceback (most recent call last):
  File "/usr/local/lib/python3.7/site-packages/django/core/handlers/exception.py", line 34, in inner
    response = get_response(request)
  File "/usr/local/lib/python3.7/site-packages/django/core/handlers/base.py", line 115, in _get_response
    response = self.process_exception_by_middleware(e, request)
  File "/usr/local/lib/python3.7/site-packages/django/core/handlers/base.py", line 113, in _get_response
    response = wrapped_callback(request, *callback_args, **callback_kwargs)
  File "./point/views.py", line 34, in ajax
    json_dict["class"] = "WARRIOR"#models.playerEPGP.objects.get(name=i.name).job
  File "/usr/local/lib/python3.7/site-packages/django/db/models/manager.py", line 82, in manager_method
    return getattr(self.get_queryset(), name)(*args, **kwargs)
  File "/usr/local/lib/python3.7/site-packages/django/db/models/query.py", line 417, in get
    self.model._meta.object_name
point.models.playerEPGP.DoesNotExist: playerEPGP matching query does not exist.
[pid: 21|app: 0|req: 6/26] 172.17.0.1 () {52 vars in 1007 bytes} [Tue Aug  4 07:53:34 2020] GET /ajax/epgploot/ => generated 73221 bytes in 63 msecs (HTTP/1.1 500) 5 headers in 156 bytes (1 switches on core 0)
Internal Server Error: /ajax/epgploot/
Traceback (most recent call last):
  File "/usr/local/lib/python3.7/site-packages/django/core/handlers/exception.py", line 34, in inner
    response = get_response(request)
  File "/usr/local/lib/python3.7/site-packages/django/core/handlers/base.py", line 115, in _get_response
    response = self.process_exception_by_middleware(e, request)
  File "/usr/local/lib/python3.7/site-packages/django/core/handlers/base.py", line 113, in _get_response
    response = wrapped_callback(request, *callback_args, **callback_kwargs)
  File "./point/views.py", line 34, in ajax
    json_dict["class"] = "WARRIOR"#models.playerEPGP.objects.get(name=i.name).job
  File "/usr/local/lib/python3.7/site-packages/django/db/models/manager.py", line 82, in manager_method
    return getattr(self.get_queryset(), name)(*args, **kwargs)
  File "/usr/local/lib/python3.7/site-packages/django/db/models/query.py", line 417, in get
    self.model._meta.object_name
point.models.playerEPGP.DoesNotExist: playerEPGP matching query does not exist.
[pid: 22|app: 0|req: 6/27] 172.17.0.1 () {52 vars in 1007 bytes} [Tue Aug  4 07:53:37 2020] GET /ajax/epgploot/ => generated 73221 bytes in 77 msecs (HTTP/1.1 500) 5 headers in 156 bytes (1 switches on core 0)
Internal Server Error: /ajax/epgploot/
Traceback (most recent call last):
  File "/usr/local/lib/python3.7/site-packages/django/core/handlers/exception.py", line 34, in inner
    response = get_response(request)
  File "/usr/local/lib/python3.7/site-packages/django/core/handlers/base.py", line 115, in _get_response
    response = self.process_exception_by_middleware(e, request)
  File "/usr/local/lib/python3.7/site-packages/django/core/handlers/base.py", line 113, in _get_response
    response = wrapped_callback(request, *callback_args, **callback_kwargs)
  File "./point/views.py", line 34, in ajax
    json_dict["class"] = "WARRIOR"#models.playerEPGP.objects.get(name=i.name).job
  File "/usr/local/lib/python3.7/site-packages/django/db/models/manager.py", line 82, in manager_method
    return getattr(self.get_queryset(), name)(*args, **kwargs)
  File "/usr/local/lib/python3.7/site-packages/django/db/models/query.py", line 417, in get
    self.model._meta.object_name
point.models.playerEPGP.DoesNotExist: playerEPGP matching query does not exist.
[pid: 23|app: 0|req: 6/28] 172.17.0.1 () {52 vars in 1007 bytes} [Tue Aug  4 07:53:38 2020] GET /ajax/epgploot/ => generated 73221 bytes in 61 msecs (HTTP/1.1 500) 5 headers in 156 bytes (1 switches on core 0)
Internal Server Error: /ajax/epgploot/
Traceback (most recent call last):
  File "/usr/local/lib/python3.7/site-packages/django/core/handlers/exception.py", line 34, in inner
    response = get_response(request)
  File "/usr/local/lib/python3.7/site-packages/django/core/handlers/base.py", line 115, in _get_response
    response = self.process_exception_by_middleware(e, request)
  File "/usr/local/lib/python3.7/site-packages/django/core/handlers/base.py", line 113, in _get_response
    response = wrapped_callback(request, *callback_args, **callback_kwargs)
  File "./point/views.py", line 34, in ajax
    json_dict["class"] = "WARRIOR"#models.playerEPGP.objects.get(name=i.name).job
  File "/usr/local/lib/python3.7/site-packages/django/db/models/manager.py", line 82, in manager_method
    return getattr(self.get_queryset(), name)(*args, **kwargs)
  File "/usr/local/lib/python3.7/site-packages/django/db/models/query.py", line 417, in get
    self.model._meta.object_name
point.models.playerEPGP.DoesNotExist: playerEPGP matching query does not exist.
[pid: 24|app: 0|req: 6/29] 172.17.0.1 () {52 vars in 1007 bytes} [Tue Aug  4 07:53:38 2020] GET /ajax/epgploot/ => generated 73221 bytes in 61 msecs (HTTP/1.1 500) 5 headers in 156 bytes (1 switches on core 0)
*** Starting uWSGI 2.0.19.1 (64bit) on [Tue Aug  4 07:53:51 2020] ***
compiled with version: 8.3.0 on 20 July 2020 10:00:56
os: Linux-4.19.76-linuxkit #1 SMP Tue May 26 11:42:35 UTC 2020
nodename: 5d70340e2b94
machine: x86_64
clock source: unix
pcre jit disabled
detected number of CPU cores: 2
current working directory: /home/ares
writing pidfile to /home/ares/log/uwsgi.pid
detected binary path: /usr/local/bin/uwsgi
*** WARNING: you are running uWSGI as root !!! (use the --uid flag) *** 
chdir() to /home/ares
your memory page size is 4096 bytes
detected max file descriptor number: 1048576
lock engine: pthread robust mutexes
thunder lock: enabled
probably another instance of uWSGI is running on the same address (0.0.0.0:8000).
bind(): Address already in use [core/socket.c line 769]
Internal Server Error: /ajax/epgploot/
Traceback (most recent call last):
  File "/usr/local/lib/python3.7/site-packages/django/core/handlers/exception.py", line 34, in inner
    response = get_response(request)
  File "/usr/local/lib/python3.7/site-packages/django/core/handlers/base.py", line 115, in _get_response
    response = self.process_exception_by_middleware(e, request)
  File "/usr/local/lib/python3.7/site-packages/django/core/handlers/base.py", line 113, in _get_response
    response = wrapped_callback(request, *callback_args, **callback_kwargs)
  File "./point/views.py", line 34, in ajax
    json_dict["class"] = "WARRIOR"#models.playerEPGP.objects.get(name=i.name).job
  File "/usr/local/lib/python3.7/site-packages/django/db/models/manager.py", line 82, in manager_method
    return getattr(self.get_queryset(), name)(*args, **kwargs)
  File "/usr/local/lib/python3.7/site-packages/django/db/models/query.py", line 417, in get
    self.model._meta.object_name
point.models.playerEPGP.DoesNotExist: playerEPGP matching query does not exist.
[pid: 25|app: 0|req: 6/30] 172.17.0.1 () {52 vars in 1007 bytes} [Tue Aug  4 07:53:53 2020] GET /ajax/epgploot/ => generated 73221 bytes in 60 msecs (HTTP/1.1 500) 5 headers in 156 bytes (1 switches on core 0)
Internal Server Error: /ajax/epgploot/
Traceback (most recent call last):
  File "/usr/local/lib/python3.7/site-packages/django/core/handlers/exception.py", line 34, in inner
    response = get_response(request)
  File "/usr/local/lib/python3.7/site-packages/django/core/handlers/base.py", line 115, in _get_response
    response = self.process_exception_by_middleware(e, request)
  File "/usr/local/lib/python3.7/site-packages/django/core/handlers/base.py", line 113, in _get_response
    response = wrapped_callback(request, *callback_args, **callback_kwargs)
  File "./point/views.py", line 34, in ajax
    json_dict["class"] = "WARRIOR"#models.playerEPGP.objects.get(name=i.name).job
  File "/usr/local/lib/python3.7/site-packages/django/db/models/manager.py", line 82, in manager_method
    return getattr(self.get_queryset(), name)(*args, **kwargs)
  File "/usr/local/lib/python3.7/site-packages/django/db/models/query.py", line 417, in get
    self.model._meta.object_name
point.models.playerEPGP.DoesNotExist: playerEPGP matching query does not exist.
[pid: 21|app: 0|req: 7/31] 172.17.0.1 () {52 vars in 1007 bytes} [Tue Aug  4 07:53:54 2020] GET /ajax/epgploot/ => generated 73221 bytes in 60 msecs (HTTP/1.1 500) 5 headers in 156 bytes (1 switches on core 0)
Internal Server Error: /ajax/epgploot/
Traceback (most recent call last):
  File "/usr/local/lib/python3.7/site-packages/django/core/handlers/exception.py", line 34, in inner
    response = get_response(request)
  File "/usr/local/lib/python3.7/site-packages/django/core/handlers/base.py", line 115, in _get_response
    response = self.process_exception_by_middleware(e, request)
  File "/usr/local/lib/python3.7/site-packages/django/core/handlers/base.py", line 113, in _get_response
    response = wrapped_callback(request, *callback_args, **callback_kwargs)
  File "./point/views.py", line 34, in ajax
    json_dict["class"] = "WARRIOR"#models.playerEPGP.objects.get(name=i.name).job
  File "/usr/local/lib/python3.7/site-packages/django/db/models/manager.py", line 82, in manager_method
    return getattr(self.get_queryset(), name)(*args, **kwargs)
  File "/usr/local/lib/python3.7/site-packages/django/db/models/query.py", line 417, in get
    self.model._meta.object_name
point.models.playerEPGP.DoesNotExist: playerEPGP matching query does not exist.
[pid: 22|app: 0|req: 7/32] 172.17.0.1 () {52 vars in 1007 bytes} [Tue Aug  4 07:53:54 2020] GET /ajax/epgploot/ => generated 73221 bytes in 61 msecs (HTTP/1.1 500) 5 headers in 156 bytes (1 switches on core 0)
uwsgi_proto_uwsgi_parser(): Success [proto/uwsgi.c line 40]
uwsgi_proto_uwsgi_parser(): Success [proto/uwsgi.c line 40]
uwsgi_proto_uwsgi_parser(): Success [proto/uwsgi.c line 40]
uwsgi_proto_uwsgi_parser(): Success [proto/uwsgi.c line 40]
uwsgi_proto_uwsgi_parser(): Success [proto/uwsgi.c line 40]
uwsgi_proto_uwsgi_parser(): Success [proto/uwsgi.c line 40]
uwsgi_proto_uwsgi_parser(): Success [proto/uwsgi.c line 40]
uwsgi_proto_uwsgi_parser(): Success [proto/uwsgi.c line 40]
